<?xml version="1.0" ?>
<!-- =================================================================================== -->
<!-- |    This document was autogenerated by xacro from m6.urdf.xacro                  | -->
<!-- |    EDITING THIS FILE BY HAND IS NOT RECOMMENDED                                 | -->
<!-- =================================================================================== -->
<robot name="m6" xmlns:xacro="http://www.ros.org/wiki/xacro">
  <!-- <link name="dummy">
  </link> -->
  <link name="base_link">
    <inertial>
      <origin rpy="0 0 0 " xyz="-0.0028085 -0.0003448 0.0270705"/>
      <mass value="2.62179"/>
      <inertia ixx="0.03211695" ixy="5.027E-05" ixz="-0.00045551" iyy="0.03627475" iyz="-3.4E-05" izz="0.05726287"/>
    </inertial>
    <visual>
      <origin rpy="0 0 0" xyz="0 0 0"/>
      <geometry>
        <mesh filename="package://titan6_general_cpp/meshes/M6_base_matt6_boxed_full.STL"/>
      </geometry>
      <material name="">
        <color rgba="0.79216 0.81961 0.93333 1"/>
      </material>
    </visual>
    <collision>
      <origin rpy="0 0 0" xyz="0 0 0"/>
      <geometry>
        <mesh filename="package://titan6_general_cpp/meshes/M6_base_matt6_boxed_full.STL"/>
      </geometry>
    </collision>
  </link>
  <link name="base1__INPUT_INTERFACE">
    <inertial>
      <origin rpy="0 0 0" xyz="0.015005 0.001775 0.015011"/>
      <mass value="1.2804"/>
      <inertia ixx="0.000533112547871023" ixy="8.52907138161489E-05" ixz="6.73224445510202E-07" iyy="0.000959826064510336" iyz="8.0840859065961E-07" izz="0.00130175668733721"/>
    </inertial>
    <visual>
      <origin rpy="0 0 0" xyz="0 0 0.015"/>
      <geometry>
        <mesh filename="package://titan6_general_cpp/meshes/M6_base_motor.STL"/>
      </geometry>
      <material name="">
        <color rgba="0.79216 0.81961 0.93333 1"/>
      </material>
    </visual>
    <collision>
      <origin rpy="0 0 0" xyz="0 0 0.015"/>
      <geometry>
        <mesh filename="package://titan6_general_cpp/meshes/M6_base_motor.STL"/>
      </geometry>
    </collision>
  </link>
  <!-- <joint name="dummy_joint" type="fixed">
  <parent link="dummy"/>
  <child link="base_link"/>
  </joint> -->
  <joint name="leg1__OUTPUT_INTERFACE" type="fixed">
    <origin rpy="0 0 3.66508333333" xyz="0.205681 0.11875 0"/>
    <parent link="base_link"/>
    <child link="base1__INPUT_INTERFACE"/>
    <axis xyz="0 0 1"/>
    <limit effort="0" velocity="0"/>
  </joint>
  <link name="shoulder1__INPUT_INTERFACE">
    <inertial>
      <origin rpy="0 0 0" xyz="-0.012554 -0.0090693 0.0503697"/>
      <mass value="1.4679"/>
      <inertia ixx="0.00085304" ixy="-4.463E-05" ixz="4.178E-05" iyy="0.0016596" iyz="4.4E-06" izz="0.00113592"/>
    </inertial>
    <visual>
      <origin rpy="0 0 0" xyz="0 0 0"/>
      <geometry>
        <mesh filename="package://titan6_general_cpp/meshes/M6_left_link1_red.STL"/>
      </geometry>
      <material name="">
        <color rgba="0.75294 0.75294 0.75294 1"/>
      </material>
    </visual>
    <collision>
      <origin rpy="0 0 0" xyz="0 0 0"/>
      <geometry>
        <mesh filename="package://titan6_general_cpp/meshes/M6_left_link1_red.STL"/>
      </geometry>
    </collision>
  </link>
  <joint name="base1" type="revolute">
    <origin rpy="0 0 3.1415" xyz="0 0 0.03105"/>
    <parent link="base1__INPUT_INTERFACE"/>
    <child link="shoulder1__INPUT_INTERFACE"/>
    <axis xyz="0 0 1"/>
    <dynamics damping=".1" friction="0.2"/>
    <limit effort="7.0" lower="-1.57075" upper="1.57075" velocity="2.208932"/>
  </joint>
  <transmission name="base1_trans">
    <type>transmission_interface/SimpleTransmission</type>
    <joint name="base1">
      <hardwareInterface>hardware_interface/EffortJointInterface</hardwareInterface>
    </joint>
    <actuator name="base1_motor">
      <hardwareInterface>hardware_interface/EffortJointInterface</hardwareInterface>
      <mechanicalReduction>300</mechanicalReduction>
    </actuator>
  </transmission>
  <link name="elbow1__INPUT_INTERFACE">
    <inertial>
      <origin rpy="0 0 0" xyz="0.27885723 0.00143862 -0.00919708"/>
      <mass value="1.58985"/>
      <inertia ixx="0.00087813" ixy="-2.653E-05" ixz="-0.00101493" iyy="0.01121522" iyz="-1.36E-05" izz="0.01137087"/>
    </inertial>
    <visual>
      <origin rpy="0 0 0" xyz="0 0 0"/>
      <geometry>
        <mesh filename="package://titan6_general_cpp/meshes/M6_link2_red.STL"/>
      </geometry>
      <material name="">
        <color rgba="0.75294 0.75294 0.75294 1"/>
      </material>
    </visual>
    <collision>
      <origin rpy="0 0 0" xyz="0 0 0"/>
      <geometry>
        <mesh filename="package://titan6_general_cpp/meshes/M6_link2_red.STL"/>
      </geometry>
    </collision>
  </link>
  <joint name="shoulder1" type="revolute">
    <origin rpy="-1.57075 0 0" xyz="0 0.00855 0.055"/>
    <parent link="shoulder1__INPUT_INTERFACE"/>
    <child link="elbow1__INPUT_INTERFACE"/>
    <axis xyz="0 0 1"/>
    <dynamics damping=".1" friction="0.2"/>
    <limit effort="7.0" lower="-1.57075" upper="1.57075" velocity="2.208932"/>
  </joint>
  <transmission name="shoulder1_trans">
    <type>transmission_interface/SimpleTransmission</type>
    <joint name="shoulder1">
      <hardwareInterface>hardware_interface/EffortJointInterface</hardwareInterface>
    </joint>
    <actuator name="shoulder1_motor">
      <hardwareInterface>hardware_interface/EffortJointInterface</hardwareInterface>
      <mechanicalReduction>300</mechanicalReduction>
    </actuator>
  </transmission>
  <link name="leg1__LAST_LINK">
    <inertial>
      <origin rpy="0 0 0" xyz="0.12121923 0 0.01723596"/>
      <mass value="0.229433"/>
      <inertia ixx="7.471E-05" ixy="0" ixz="7.798E-05" iyy="0.00331684" iyz="0" izz="0.0033262"/>
    </inertial>
    <visual>
      <origin rpy="0 0 0" xyz="0 0 0"/>
      <geometry>
        <mesh filename="package://titan6_general_cpp/meshes/M6_link3_red.STL"/>
      </geometry>
      <material name="">
        <color rgba="0.75294 0.75294 0.75294 1"/>
      </material>
    </visual>
    <collision>
      <origin rpy="0 0 0" xyz="0 0 0"/>
      <geometry>
        <mesh filename="package://titan6_general_cpp/meshes/M6_link3_red.STL"/>
      </geometry>
    </collision>
  </link>
  <joint name="elbow1" type="revolute">
    <origin rpy="3.1415 0 0" xyz="0.3195 0 -0.03105"/>
    <parent link="elbow1__INPUT_INTERFACE"/>
    <child link="leg1__LAST_LINK"/>
    <axis xyz="0 0 1"/>
    <dynamics damping=".1" friction="0.2"/>
    <limit effort="7.0" lower="-3.1415" upper="3.1415" velocity="2.208932"/>
  </joint>
  <transmission name="elbow1_trans">
    <type>transmission_interface/SimpleTransmission</type>
    <joint name="elbow1">
      <hardwareInterface>hardware_interface/EffortJointInterface</hardwareInterface>
    </joint>
    <actuator name="elbow1_motor">
      <hardwareInterface>hardware_interface/EffortJointInterface</hardwareInterface>
      <mechanicalReduction>300</mechanicalReduction>
    </actuator>
  </transmission>
  <link name="base3__INPUT_INTERFACE">
    <inertial>
      <origin rpy="0 0 0" xyz="0.015005 0.001775 0.015011"/>
      <mass value="1.2804"/>
      <inertia ixx="0.000533112547871023" ixy="8.52907138161489E-05" ixz="6.73224445510202E-07" iyy="0.000959826064510336" iyz="8.0840859065961E-07" izz="0.00130175668733721"/>
    </inertial>
    <visual>
      <origin rpy="0 0 0" xyz="0 0 0.015"/>
      <geometry>
        <mesh filename="package://titan6_general_cpp/meshes/M6_base_motor.STL"/>
      </geometry>
      <material name="">
        <color rgba="0.79216 0.81961 0.93333 1"/>
      </material>
    </visual>
    <collision>
      <origin rpy="0 0 0" xyz="0 0 0.015"/>
      <geometry>
        <mesh filename="package://titan6_general_cpp/meshes/M6_base_motor.STL"/>
      </geometry>
    </collision>
  </link>
  <joint name="leg3__OUTPUT_INTERFACE" type="fixed">
    <origin rpy="0 0 4.71225" xyz="0 0.1875 0"/>
    <parent link="base_link"/>
    <child link="base3__INPUT_INTERFACE"/>
    <axis xyz="0 0 1"/>
    <limit effort="0" velocity="0"/>
  </joint>
  <link name="shoulder3__INPUT_INTERFACE">
    <inertial>
      <origin rpy="0 0 0" xyz="-0.012554 -0.0090693 0.0503697"/>
      <mass value="1.4679"/>
      <inertia ixx="0.00085304" ixy="-4.463E-05" ixz="4.178E-05" iyy="0.0016596" iyz="4.4E-06" izz="0.00113592"/>
    </inertial>
    <visual>
      <origin rpy="0 0 0" xyz="0 0 0"/>
      <geometry>
        <mesh filename="package://titan6_general_cpp/meshes/M6_left_link1_red.STL"/>
      </geometry>
      <material name="">
        <color rgba="0.75294 0.75294 0.75294 1"/>
      </material>
    </visual>
    <collision>
      <origin rpy="0 0 0" xyz="0 0 0"/>
      <geometry>
        <mesh filename="package://titan6_general_cpp/meshes/M6_left_link1_red.STL"/>
      </geometry>
    </collision>
  </link>
  <joint name="base3" type="revolute">
    <origin rpy="0 0 3.1415" xyz="0 0 0.03105"/>
    <parent link="base3__INPUT_INTERFACE"/>
    <child link="shoulder3__INPUT_INTERFACE"/>
    <axis xyz="0 0 1"/>
    <dynamics damping=".1" friction="0.2"/>
    <limit effort="7.0" lower="-1.57075" upper="1.57075" velocity="2.208932"/>
  </joint>
  <transmission name="base3_trans">
    <type>transmission_interface/SimpleTransmission</type>
    <joint name="base3">
      <hardwareInterface>hardware_interface/EffortJointInterface</hardwareInterface>
    </joint>
    <actuator name="base3_motor">
      <hardwareInterface>hardware_interface/EffortJointInterface</hardwareInterface>
      <mechanicalReduction>300</mechanicalReduction>
    </actuator>
  </transmission>
  <link name="elbow3__INPUT_INTERFACE">
    <inertial>
      <origin rpy="0 0 0" xyz="0.27885723 0.00143862 -0.00919708"/>
      <mass value="1.58985"/>
      <inertia ixx="0.00087813" ixy="-2.653E-05" ixz="-0.00101493" iyy="0.01121522" iyz="-1.36E-05" izz="0.01137087"/>
    </inertial>
    <visual>
      <origin rpy="0 0 0" xyz="0 0 0"/>
      <geometry>
        <mesh filename="package://titan6_general_cpp/meshes/M6_link2_red.STL"/>
      </geometry>
      <material name="">
        <color rgba="0.75294 0.75294 0.75294 1"/>
      </material>
    </visual>
    <collision>
      <origin rpy="0 0 0" xyz="0 0 0"/>
      <geometry>
        <mesh filename="package://titan6_general_cpp/meshes/M6_link2_red.STL"/>
      </geometry>
    </collision>
  </link>
  <joint name="shoulder3" type="revolute">
    <origin rpy="-1.57075 0 0" xyz="0 0.00855 0.055"/>
    <parent link="shoulder3__INPUT_INTERFACE"/>
    <child link="elbow3__INPUT_INTERFACE"/>
    <axis xyz="0 0 1"/>
    <dynamics damping=".1" friction="0.2"/>
    <limit effort="7.0" lower="-1.57075" upper="1.57075" velocity="2.208932"/>
  </joint>
  <transmission name="shoulder3_trans">
    <type>transmission_interface/SimpleTransmission</type>
    <joint name="shoulder3">
      <hardwareInterface>hardware_interface/EffortJointInterface</hardwareInterface>
    </joint>
    <actuator name="shoulder3_motor">
      <hardwareInterface>hardware_interface/EffortJointInterface</hardwareInterface>
      <mechanicalReduction>300</mechanicalReduction>
    </actuator>
  </transmission>
  <link name="leg3__LAST_LINK">
    <inertial>
      <origin rpy="0 0 0" xyz="0.12121923 0 0.01723596"/>
      <mass value="0.229433"/>
      <inertia ixx="7.471E-05" ixy="0" ixz="7.798E-05" iyy="0.00331684" iyz="0" izz="0.0033262"/>
    </inertial>
    <visual>
      <origin rpy="0 0 0" xyz="0 0 0"/>
      <geometry>
        <mesh filename="package://titan6_general_cpp/meshes/M6_link3_red.STL"/>
      </geometry>
      <material name="">
        <color rgba="0.75294 0.75294 0.75294 1"/>
      </material>
    </visual>
    <collision>
      <origin rpy="0 0 0" xyz="0 0 0"/>
      <geometry>
        <mesh filename="package://titan6_general_cpp/meshes/M6_link3_red.STL"/>
      </geometry>
    </collision>
  </link>
  <joint name="elbow3" type="revolute">
    <origin rpy="3.1415 0 0" xyz="0.3195 0 -0.03105"/>
    <parent link="elbow3__INPUT_INTERFACE"/>
    <child link="leg3__LAST_LINK"/>
    <axis xyz="0 0 1"/>
    <dynamics damping=".1" friction="0.2"/>
    <limit effort="7.0" lower="-3.1415" upper="3.1415" velocity="2.208932"/>
  </joint>
  <transmission name="elbow3_trans">
    <type>transmission_interface/SimpleTransmission</type>
    <joint name="elbow3">
      <hardwareInterface>hardware_interface/EffortJointInterface</hardwareInterface>
    </joint>
    <actuator name="elbow3_motor">
      <hardwareInterface>hardware_interface/EffortJointInterface</hardwareInterface>
      <mechanicalReduction>300</mechanicalReduction>
    </actuator>
  </transmission>
  <link name="base5__INPUT_INTERFACE">
    <inertial>
      <origin rpy="0 0 0" xyz="0.015005 0.001775 0.015011"/>
      <mass value="1.2804"/>
      <inertia ixx="0.000533112547871023" ixy="8.52907138161489E-05" ixz="6.73224445510202E-07" iyy="0.000959826064510336" iyz="8.0840859065961E-07" izz="0.00130175668733721"/>
    </inertial>
    <visual>
      <origin rpy="0 0 0" xyz="0 0 0.015"/>
      <geometry>
        <mesh filename="package://titan6_general_cpp/meshes/M6_base_motor.STL"/>
      </geometry>
      <material name="">
        <color rgba="0.79216 0.81961 0.93333 1"/>
      </material>
    </visual>
    <collision>
      <origin rpy="0 0 0" xyz="0 0 0.015"/>
      <geometry>
        <mesh filename="package://titan6_general_cpp/meshes/M6_base_motor.STL"/>
      </geometry>
    </collision>
  </link>
  <joint name="leg5__OUTPUT_INTERFACE" type="fixed">
    <origin rpy="0 0 5.75941666667" xyz="-0.205681 0.11875 0"/>
    <parent link="base_link"/>
    <child link="base5__INPUT_INTERFACE"/>
    <axis xyz="0 0 1"/>
    <limit effort="0" velocity="0"/>
  </joint>
  <link name="shoulder5__INPUT_INTERFACE">
    <inertial>
      <origin rpy="0 0 0" xyz="-0.012554 -0.0090693 0.0503697"/>
      <mass value="1.4679"/>
      <inertia ixx="0.00085304" ixy="-4.463E-05" ixz="4.178E-05" iyy="0.0016596" iyz="4.4E-06" izz="0.00113592"/>
    </inertial>
    <visual>
      <origin rpy="0 0 0" xyz="0 0 0"/>
      <geometry>
        <mesh filename="package://titan6_general_cpp/meshes/M6_left_link1_red.STL"/>
      </geometry>
      <material name="">
        <color rgba="0.75294 0.75294 0.75294 1"/>
      </material>
    </visual>
    <collision>
      <origin rpy="0 0 0" xyz="0 0 0"/>
      <geometry>
        <mesh filename="package://titan6_general_cpp/meshes/M6_left_link1_red.STL"/>
      </geometry>
    </collision>
  </link>
  <joint name="base5" type="revolute">
    <origin rpy="0 0 3.1415" xyz="0 0 0.03105"/>
    <parent link="base5__INPUT_INTERFACE"/>
    <child link="shoulder5__INPUT_INTERFACE"/>
    <axis xyz="0 0 1"/>
    <dynamics damping=".1" friction="0.2"/>
    <limit effort="7.0" lower="-1.57075" upper="1.57075" velocity="2.208932"/>
  </joint>
  <transmission name="base5_trans">
    <type>transmission_interface/SimpleTransmission</type>
    <joint name="base5">
      <hardwareInterface>hardware_interface/EffortJointInterface</hardwareInterface>
    </joint>
    <actuator name="base5_motor">
      <hardwareInterface>hardware_interface/EffortJointInterface</hardwareInterface>
      <mechanicalReduction>300</mechanicalReduction>
    </actuator>
  </transmission>
  <link name="elbow5__INPUT_INTERFACE">
    <inertial>
      <origin rpy="0 0 0" xyz="0.27885723 0.00143862 -0.00919708"/>
      <mass value="1.58985"/>
      <inertia ixx="0.00087813" ixy="-2.653E-05" ixz="-0.00101493" iyy="0.01121522" iyz="-1.36E-05" izz="0.01137087"/>
    </inertial>
    <visual>
      <origin rpy="0 0 0" xyz="0 0 0"/>
      <geometry>
        <mesh filename="package://titan6_general_cpp/meshes/M6_link2_red.STL"/>
      </geometry>
      <material name="">
        <color rgba="0.75294 0.75294 0.75294 1"/>
      </material>
    </visual>
    <collision>
      <origin rpy="0 0 0" xyz="0 0 0"/>
      <geometry>
        <mesh filename="package://titan6_general_cpp/meshes/M6_link2_red.STL"/>
      </geometry>
    </collision>
  </link>
  <joint name="shoulder5" type="revolute">
    <origin rpy="-1.57075 0 0" xyz="0 0.00855 0.055"/>
    <parent link="shoulder5__INPUT_INTERFACE"/>
    <child link="elbow5__INPUT_INTERFACE"/>
    <axis xyz="0 0 1"/>
    <dynamics damping=".1" friction="0.2"/>
    <limit effort="7.0" lower="-1.57075" upper="1.57075" velocity="2.208932"/>
  </joint>
  <transmission name="shoulder5_trans">
    <type>transmission_interface/SimpleTransmission</type>
    <joint name="shoulder5">
      <hardwareInterface>hardware_interface/EffortJointInterface</hardwareInterface>
    </joint>
    <actuator name="shoulder5_motor">
      <hardwareInterface>hardware_interface/EffortJointInterface</hardwareInterface>
      <mechanicalReduction>300</mechanicalReduction>
    </actuator>
  </transmission>
  <link name="leg5__LAST_LINK">
    <inertial>
      <origin rpy="0 0 0" xyz="0.12121923 0 0.01723596"/>
      <mass value="0.229433"/>
      <inertia ixx="7.471E-05" ixy="0" ixz="7.798E-05" iyy="0.00331684" iyz="0" izz="0.0033262"/>
    </inertial>
    <visual>
      <origin rpy="0 0 0" xyz="0 0 0"/>
      <geometry>
        <mesh filename="package://titan6_general_cpp/meshes/M6_link3_red.STL"/>
      </geometry>
      <material name="">
        <color rgba="0.75294 0.75294 0.75294 1"/>
      </material>
    </visual>
    <collision>
      <origin rpy="0 0 0" xyz="0 0 0"/>
      <geometry>
        <mesh filename="package://titan6_general_cpp/meshes/M6_link3_red.STL"/>
      </geometry>
    </collision>
  </link>
  <joint name="elbow5" type="revolute">
    <origin rpy="3.1415 0 0" xyz="0.3195 0 -0.03105"/>
    <parent link="elbow5__INPUT_INTERFACE"/>
    <child link="leg5__LAST_LINK"/>
    <axis xyz="0 0 1"/>
    <dynamics damping=".1" friction="0.2"/>
    <limit effort="7.0" lower="-3.1415" upper="3.1415" velocity="2.208932"/>
  </joint>
  <transmission name="elbow5_trans">
    <type>transmission_interface/SimpleTransmission</type>
    <joint name="elbow5">
      <hardwareInterface>hardware_interface/EffortJointInterface</hardwareInterface>
    </joint>
    <actuator name="elbow5_motor">
      <hardwareInterface>hardware_interface/EffortJointInterface</hardwareInterface>
      <mechanicalReduction>300</mechanicalReduction>
    </actuator>
  </transmission>
  <link name="base2__INPUT_INTERFACE">
    <inertial>
      <origin rpy="0 0 0" xyz="0.015005 0.001775 0.015011"/>
      <mass value="1.2804"/>
      <inertia ixx="0.000533112547871023" ixy="8.52907138161489E-05" ixz="6.73224445510202E-07" iyy="0.000959826064510336" iyz="8.0840859065961E-07" izz="0.00130175668733721"/>
    </inertial>
    <visual>
      <origin rpy="0 0 0" xyz="0 0 0.015"/>
      <geometry>
        <mesh filename="package://titan6_general_cpp/meshes/M6_base_motor.STL"/>
      </geometry>
      <material name="">
        <color rgba="0.79216 0.81961 0.93333 1"/>
      </material>
    </visual>
    <collision>
      <origin rpy="0 0 0" xyz="0 0 0.015"/>
      <geometry>
        <mesh filename="package://titan6_general_cpp/meshes/M6_base_motor.STL"/>
      </geometry>
    </collision>
  </link>
  <joint name="leg2__OUTPUT_INTERFACE" type="fixed">
    <origin rpy="0 0 2.61791666667" xyz="0.205681 -0.11875 0"/>
    <parent link="base_link"/>
    <child link="base2__INPUT_INTERFACE"/>
    <axis xyz="0 0 1"/>
    <limit effort="0" velocity="0"/>
  </joint>
  <link name="shoulder2__INPUT_INTERFACE">
    <inertial>
      <origin rpy="0 0 0" xyz="-0.012554 -0.0090693 -0.0503697"/>
      <mass value="1.4679"/>
      <inertia ixx="0.00085304" ixy="-4.463E-05" ixz="-4.178E-05" iyy="0.0016596" iyz="-4.4E-06" izz="0.00113592"/>
    </inertial>
    <visual>
      <origin rpy="0 0 0" xyz="0 0 0"/>
      <geometry>
        <mesh filename="package://titan6_general_cpp/meshes/M6_right_link1_red.STL"/>
      </geometry>
      <material name="">
        <color rgba="0.75294 0.75294 0.75294 1"/>
      </material>
    </visual>
    <collision>
      <origin rpy="0 0 0" xyz="0 0 0"/>
      <geometry>
        <mesh filename="package://titan6_general_cpp/meshes/M6_right_link1_red.STL"/>
      </geometry>
    </collision>
  </link>
  <joint name="base2" type="revolute">
    <origin rpy="0 0 0" xyz="0 0 0.03105"/>
    <parent link="base2__INPUT_INTERFACE"/>
    <child link="shoulder2__INPUT_INTERFACE"/>
    <axis xyz="0 0 1"/>
    <dynamics damping=".1" friction="0.2"/>
    <limit effort="7.0" lower="-1.57075" upper="1.57075" velocity="2.208932"/>
  </joint>
  <transmission name="base2_trans">
    <type>transmission_interface/SimpleTransmission</type>
    <joint name="base2">
      <hardwareInterface>hardware_interface/EffortJointInterface</hardwareInterface>
    </joint>
    <actuator name="base2_motor">
      <hardwareInterface>hardware_interface/EffortJointInterface</hardwareInterface>
      <mechanicalReduction>300</mechanicalReduction>
    </actuator>
  </transmission>
  <link name="elbow2__INPUT_INTERFACE">
    <inertial>
      <origin rpy="0 0 0" xyz="0.27885723 0.00143862 -0.00919708"/>
      <mass value="1.58985"/>
      <inertia ixx="0.00087813" ixy="-2.653E-05" ixz="-0.00101493" iyy="0.01121522" iyz="-1.36E-05" izz="0.01137087"/>
    </inertial>
    <visual>
      <origin rpy="0 0 0" xyz="0 0 0"/>
      <geometry>
        <mesh filename="package://titan6_general_cpp/meshes/M6_link2_red.STL"/>
      </geometry>
      <material name="">
        <color rgba="0.75294 0.75294 0.75294 1"/>
      </material>
    </visual>
    <collision>
      <origin rpy="0 0 0" xyz="0 0 0"/>
      <geometry>
        <mesh filename="package://titan6_general_cpp/meshes/M6_link2_red.STL"/>
      </geometry>
    </collision>
  </link>
  <joint name="shoulder2" type="revolute">
    <origin rpy="1.57075 0 3.1415" xyz="0 0.00855 0.055"/>
    <parent link="shoulder2__INPUT_INTERFACE"/>
    <child link="elbow2__INPUT_INTERFACE"/>
    <axis xyz="0 0 1"/>
    <dynamics damping=".1" friction="0.2"/>
    <limit effort="7.0" lower="-1.57075" upper="1.57075" velocity="2.208932"/>
  </joint>
  <transmission name="shoulder2_trans">
    <type>transmission_interface/SimpleTransmission</type>
    <joint name="shoulder2">
      <hardwareInterface>hardware_interface/EffortJointInterface</hardwareInterface>
    </joint>
    <actuator name="shoulder2_motor">
      <hardwareInterface>hardware_interface/EffortJointInterface</hardwareInterface>
      <mechanicalReduction>300</mechanicalReduction>
    </actuator>
  </transmission>
  <link name="leg2__LAST_LINK">
    <inertial>
      <origin rpy="0 0 0" xyz="0.12121923 0 0.01723596"/>
      <mass value="0.229433"/>
      <inertia ixx="7.471E-05" ixy="0" ixz="7.798E-05" iyy="0.00331684" iyz="0" izz="0.0033262"/>
    </inertial>
    <visual>
      <origin rpy="0 0 0" xyz="0 0 0"/>
      <geometry>
        <mesh filename="package://titan6_general_cpp/meshes/M6_link3_red.STL"/>
      </geometry>
      <material name="">
        <color rgba="0.75294 0.75294 0.75294 1"/>
      </material>
    </visual>
    <collision>
      <origin rpy="0 0 0" xyz="0 0 0"/>
      <geometry>
        <mesh filename="package://titan6_general_cpp/meshes/M6_link3_red.STL"/>
      </geometry>
    </collision>
  </link>
  <joint name="elbow2" type="revolute">
    <origin rpy="3.1415 0 0" xyz="0.3195 0 -0.03105"/>
    <parent link="elbow2__INPUT_INTERFACE"/>
    <child link="leg2__LAST_LINK"/>
    <axis xyz="0 0 1"/>
    <dynamics damping=".1" friction="0.2"/>
    <limit effort="7.0" lower="-3.1415" upper="3.1415" velocity="2.208932"/>
  </joint>
  <transmission name="elbow2_trans">
    <type>transmission_interface/SimpleTransmission</type>
    <joint name="elbow2">
      <hardwareInterface>hardware_interface/EffortJointInterface</hardwareInterface>
    </joint>
    <actuator name="elbow2_motor">
      <hardwareInterface>hardware_interface/EffortJointInterface</hardwareInterface>
      <mechanicalReduction>300</mechanicalReduction>
    </actuator>
  </transmission>
  <link name="base4__INPUT_INTERFACE">
    <inertial>
      <origin rpy="0 0 0" xyz="0.015005 0.001775 0.015011"/>
      <mass value="1.2804"/>
      <inertia ixx="0.000533112547871023" ixy="8.52907138161489E-05" ixz="6.73224445510202E-07" iyy="0.000959826064510336" iyz="8.0840859065961E-07" izz="0.00130175668733721"/>
    </inertial>
    <visual>
      <origin rpy="0 0 0" xyz="0 0 0.015"/>
      <geometry>
        <mesh filename="package://titan6_general_cpp/meshes/M6_base_motor.STL"/>
      </geometry>
      <material name="">
        <color rgba="0.79216 0.81961 0.93333 1"/>
      </material>
    </visual>
    <collision>
      <origin rpy="0 0 0" xyz="0 0 0.015"/>
      <geometry>
        <mesh filename="package://titan6_general_cpp/meshes/M6_base_motor.STL"/>
      </geometry>
    </collision>
  </link>
  <joint name="leg4__OUTPUT_INTERFACE" type="fixed">
    <origin rpy="0 0 1.57075" xyz="0 -0.1875 0"/>
    <parent link="base_link"/>
    <child link="base4__INPUT_INTERFACE"/>
    <axis xyz="0 0 1"/>
    <limit effort="0" velocity="0"/>
  </joint>
  <link name="shoulder4__INPUT_INTERFACE">
    <inertial>
      <origin rpy="0 0 0" xyz="-0.012554 -0.0090693 -0.0503697"/>
      <mass value="1.4679"/>
      <inertia ixx="0.00085304" ixy="-4.463E-05" ixz="-4.178E-05" iyy="0.0016596" iyz="-4.4E-06" izz="0.00113592"/>
    </inertial>
    <visual>
      <origin rpy="0 0 0" xyz="0 0 0"/>
      <geometry>
        <mesh filename="package://titan6_general_cpp/meshes/M6_right_link1_red.STL"/>
      </geometry>
      <material name="">
        <color rgba="0.75294 0.75294 0.75294 1"/>
      </material>
    </visual>
    <collision>
      <origin rpy="0 0 0" xyz="0 0 0"/>
      <geometry>
        <mesh filename="package://titan6_general_cpp/meshes/M6_right_link1_red.STL"/>
      </geometry>
    </collision>
  </link>
  <joint name="base4" type="revolute">
    <origin rpy="0 0 0" xyz="0 0 0.03105"/>
    <parent link="base4__INPUT_INTERFACE"/>
    <child link="shoulder4__INPUT_INTERFACE"/>
    <axis xyz="0 0 1"/>
    <dynamics damping=".1" friction="0.2"/>
    <limit effort="7.0" lower="-1.57075" upper="1.57075" velocity="2.208932"/>
  </joint>
  <transmission name="base4_trans">
    <type>transmission_interface/SimpleTransmission</type>
    <joint name="base4">
      <hardwareInterface>hardware_interface/EffortJointInterface</hardwareInterface>
    </joint>
    <actuator name="base4_motor">
      <hardwareInterface>hardware_interface/EffortJointInterface</hardwareInterface>
      <mechanicalReduction>300</mechanicalReduction>
    </actuator>
  </transmission>
  <link name="elbow4__INPUT_INTERFACE">
    <inertial>
      <origin rpy="0 0 0" xyz="0.27885723 0.00143862 -0.00919708"/>
      <mass value="1.58985"/>
      <inertia ixx="0.00087813" ixy="-2.653E-05" ixz="-0.00101493" iyy="0.01121522" iyz="-1.36E-05" izz="0.01137087"/>
    </inertial>
    <visual>
      <origin rpy="0 0 0" xyz="0 0 0"/>
      <geometry>
        <mesh filename="package://titan6_general_cpp/meshes/M6_link2_red.STL"/>
      </geometry>
      <material name="">
        <color rgba="0.75294 0.75294 0.75294 1"/>
      </material>
    </visual>
    <collision>
      <origin rpy="0 0 0" xyz="0 0 0"/>
      <geometry>
        <mesh filename="package://titan6_general_cpp/meshes/M6_link2_red.STL"/>
      </geometry>
    </collision>
  </link>
  <joint name="shoulder4" type="revolute">
    <origin rpy="1.57075 0 3.1415" xyz="0 0.00855 0.055"/>
    <parent link="shoulder4__INPUT_INTERFACE"/>
    <child link="elbow4__INPUT_INTERFACE"/>
    <axis xyz="0 0 1"/>
    <dynamics damping=".1" friction="0.2"/>
    <limit effort="7.0" lower="-1.57075" upper="1.57075" velocity="2.208932"/>
  </joint>
  <transmission name="shoulder4_trans">
    <type>transmission_interface/SimpleTransmission</type>
    <joint name="shoulder4">
      <hardwareInterface>hardware_interface/EffortJointInterface</hardwareInterface>
    </joint>
    <actuator name="shoulder4_motor">
      <hardwareInterface>hardware_interface/EffortJointInterface</hardwareInterface>
      <mechanicalReduction>300</mechanicalReduction>
    </actuator>
  </transmission>
  <link name="leg4__LAST_LINK">
    <inertial>
      <origin rpy="0 0 0" xyz="0.12121923 0 0.01723596"/>
      <mass value="0.229433"/>
      <inertia ixx="7.471E-05" ixy="0" ixz="7.798E-05" iyy="0.00331684" iyz="0" izz="0.0033262"/>
    </inertial>
    <visual>
      <origin rpy="0 0 0" xyz="0 0 0"/>
      <geometry>
        <mesh filename="package://titan6_general_cpp/meshes/M6_link3_red.STL"/>
      </geometry>
      <material name="">
        <color rgba="0.75294 0.75294 0.75294 1"/>
      </material>
    </visual>
    <collision>
      <origin rpy="0 0 0" xyz="0 0 0"/>
      <geometry>
        <mesh filename="package://titan6_general_cpp/meshes/M6_link3_red.STL"/>
      </geometry>
    </collision>
  </link>
  <joint name="elbow4" type="revolute">
    <origin rpy="3.1415 0 0" xyz="0.3195 0 -0.03105"/>
    <parent link="elbow4__INPUT_INTERFACE"/>
    <child link="leg4__LAST_LINK"/>
    <axis xyz="0 0 1"/>
    <dynamics damping=".1" friction="0.2"/>
    <limit effort="7.0" lower="-3.1415" upper="3.1415" velocity="2.208932"/>
  </joint>
  <transmission name="elbow4_trans">
    <type>transmission_interface/SimpleTransmission</type>
    <joint name="elbow4">
      <hardwareInterface>hardware_interface/EffortJointInterface</hardwareInterface>
    </joint>
    <actuator name="elbow4_motor">
      <hardwareInterface>hardware_interface/EffortJointInterface</hardwareInterface>
      <mechanicalReduction>300</mechanicalReduction>
    </actuator>
  </transmission>
  <link name="base6__INPUT_INTERFACE">
    <inertial>
      <origin rpy="0 0 0" xyz="0.015005 0.001775 0.015011"/>
      <mass value="1.2804"/>
      <inertia ixx="0.000533112547871023" ixy="8.52907138161489E-05" ixz="6.73224445510202E-07" iyy="0.000959826064510336" iyz="8.0840859065961E-07" izz="0.00130175668733721"/>
    </inertial>
    <visual>
      <origin rpy="0 0 0" xyz="0 0 0.015"/>
      <geometry>
        <mesh filename="package://titan6_general_cpp/meshes/M6_base_motor.STL"/>
      </geometry>
      <material name="">
        <color rgba="0.79216 0.81961 0.93333 1"/>
      </material>
    </visual>
    <collision>
      <origin rpy="0 0 0" xyz="0 0 0.015"/>
      <geometry>
        <mesh filename="package://titan6_general_cpp/meshes/M6_base_motor.STL"/>
      </geometry>
    </collision>
  </link>
  <joint name="leg6__OUTPUT_INTERFACE" type="fixed">
    <origin rpy="0 0 0.523583333333" xyz="-0.205681 -0.11875 0"/>
    <parent link="base_link"/>
    <child link="base6__INPUT_INTERFACE"/>
    <axis xyz="0 0 1"/>
    <limit effort="0" velocity="0"/>
  </joint>
  <link name="shoulder6__INPUT_INTERFACE">
    <inertial>
      <origin rpy="0 0 0" xyz="-0.012554 -0.0090693 -0.0503697"/>
      <mass value="1.4679"/>
      <inertia ixx="0.00085304" ixy="-4.463E-05" ixz="-4.178E-05" iyy="0.0016596" iyz="-4.4E-06" izz="0.00113592"/>
    </inertial>
    <visual>
      <origin rpy="0 0 0" xyz="0 0 0"/>
      <geometry>
        <mesh filename="package://titan6_general_cpp/meshes/M6_right_link1_red.STL"/>
      </geometry>
      <material name="">
        <color rgba="0.75294 0.75294 0.75294 1"/>
      </material>
    </visual>
    <collision>
      <origin rpy="0 0 0" xyz="0 0 0"/>
      <geometry>
        <mesh filename="package://titan6_general_cpp/meshes/M6_right_link1_red.STL"/>
      </geometry>
    </collision>
  </link>
  <joint name="base6" type="revolute">
    <origin rpy="0 0 0" xyz="0 0 0.03105"/>
    <parent link="base6__INPUT_INTERFACE"/>
    <child link="shoulder6__INPUT_INTERFACE"/>
    <axis xyz="0 0 1"/>
    <dynamics damping=".1" friction="0.2"/>
    <limit effort="7.0" lower="-1.57075" upper="1.57075" velocity="2.208932"/>
  </joint>
  <transmission name="base6_trans">
    <type>transmission_interface/SimpleTransmission</type>
    <joint name="base6">
      <hardwareInterface>hardware_interface/EffortJointInterface</hardwareInterface>
    </joint>
    <actuator name="base6_motor">
      <hardwareInterface>hardware_interface/EffortJointInterface</hardwareInterface>
      <mechanicalReduction>300</mechanicalReduction>
    </actuator>
  </transmission>
  <link name="elbow6__INPUT_INTERFACE">
    <inertial>
      <origin rpy="0 0 0" xyz="0.27885723 0.00143862 -0.00919708"/>
      <mass value="1.58985"/>
      <inertia ixx="0.00087813" ixy="-2.653E-05" ixz="-0.00101493" iyy="0.01121522" iyz="-1.36E-05" izz="0.01137087"/>
    </inertial>
    <visual>
      <origin rpy="0 0 0" xyz="0 0 0"/>
      <geometry>
        <mesh filename="package://titan6_general_cpp/meshes/M6_link2_red.STL"/>
      </geometry>
      <material name="">
        <color rgba="0.75294 0.75294 0.75294 1"/>
      </material>
    </visual>
    <collision>
      <origin rpy="0 0 0" xyz="0 0 0"/>
      <geometry>
        <mesh filename="package://titan6_general_cpp/meshes/M6_link2_red.STL"/>
      </geometry>
    </collision>
  </link>
  <joint name="shoulder6" type="revolute">
    <origin rpy="1.57075 0 3.1415" xyz="0 0.00855 0.055"/>
    <parent link="shoulder6__INPUT_INTERFACE"/>
    <child link="elbow6__INPUT_INTERFACE"/>
    <axis xyz="0 0 1"/>
    <dynamics damping=".1" friction="0.2"/>
    <limit effort="7.0" lower="-1.57075" upper="1.57075" velocity="2.208932"/>
  </joint>
  <transmission name="shoulder6_trans">
    <type>transmission_interface/SimpleTransmission</type>
    <joint name="shoulder6">
      <hardwareInterface>hardware_interface/EffortJointInterface</hardwareInterface>
    </joint>
    <actuator name="shoulder6_motor">
      <hardwareInterface>hardware_interface/EffortJointInterface</hardwareInterface>
      <mechanicalReduction>300</mechanicalReduction>
    </actuator>
  </transmission>
  <link name="leg6__LAST_LINK">
    <inertial>
      <origin rpy="0 0 0" xyz="0.12121923 0 0.01723596"/>
      <mass value="0.229433"/>
      <inertia ixx="7.471E-05" ixy="0" ixz="7.798E-05" iyy="0.00331684" iyz="0" izz="0.0033262"/>
    </inertial>
    <visual>
      <origin rpy="0 0 0" xyz="0 0 0"/>
      <geometry>
        <mesh filename="package://titan6_general_cpp/meshes/M6_link3_red.STL"/>
      </geometry>
      <material name="">
        <color rgba="0.75294 0.75294 0.75294 1"/>
      </material>
    </visual>
    <collision>
      <origin rpy="0 0 0" xyz="0 0 0"/>
      <geometry>
        <mesh filename="package://titan6_general_cpp/meshes/M6_link3_red.STL"/>
      </geometry>
    </collision>
  </link>
  <joint name="elbow6" type="revolute">
    <origin rpy="3.1415 0 0" xyz="0.3195 0 -0.03105"/>
    <parent link="elbow6__INPUT_INTERFACE"/>
    <child link="leg6__LAST_LINK"/>
    <axis xyz="0 0 1"/>
    <dynamics damping=".1" friction="0.2"/>
    <limit effort="7.0" lower="-3.1415" upper="3.1415" velocity="2.208932"/>
  </joint>
  <transmission name="elbow6_trans">
    <type>transmission_interface/SimpleTransmission</type>
    <joint name="elbow6">
      <hardwareInterface>hardware_interface/EffortJointInterface</hardwareInterface>
    </joint>
    <actuator name="elbow6_motor">
      <hardwareInterface>hardware_interface/EffortJointInterface</hardwareInterface>
      <mechanicalReduction>300</mechanicalReduction>
    </actuator>
  </transmission>
  <!-- ros_control plugin -->
  <gazebo>
    <plugin filename="libgazebo_ros_control.so" name="gazebo_ros_control">
      <robotNamespace>/m6</robotNamespace>
      <robotSimType>gazebo_ros_control/DefaultRobotHWSim</robotSimType>
      <legacyModeNS>true</legacyModeNS>
    </plugin>
  </gazebo>
  <gazebo reference="base_link">
    <material>Gazebo/Grey</material>
  </gazebo>
  <gazebo reference="base1__INPUT_INTERFACE">
    <material>Gazebo/Red</material>
    <static>false</static>
    <selfCollide>true</selfCollide>
  </gazebo>
  <gazebo reference="shoulder1__INPUT_INTERFACE">
    <material>Gazebo/Grey</material>
    <static>false</static>
    <selfCollide>true</selfCollide>
  </gazebo>
  <gazebo reference="elbow1__INPUT_INTERFACE">
    <static>false</static>
    <selfCollide>true</selfCollide>
  </gazebo>
  <gazebo reference="leg1__LAST_LINK">
    <material>Gazebo/Grey</material>
    <mu1>0.9</mu1>
    <mu2>0.9</mu2>
    <static>false</static>
    <selfCollide>true</selfCollide>
  </gazebo>
  <gazebo reference="base2__INPUT_INTERFACE">
    <material>Gazebo/Red</material>
    <static>false</static>
    <selfCollide>true</selfCollide>
  </gazebo>
  <gazebo reference="shoulder2__INPUT_INTERFACE">
    <material>Gazebo/Grey</material>
    <static>false</static>
    <selfCollide>true</selfCollide>
  </gazebo>
  <gazebo reference="elbow2__INPUT_INTERFACE">
    <static>false</static>
    <selfCollide>true</selfCollide>
  </gazebo>
  <gazebo reference="leg2__LAST_LINK">
    <material>Gazebo/Grey</material>
    <mu1>0.9</mu1>
    <mu2>0.9</mu2>
    <static>false</static>
    <selfCollide>true</selfCollide>
  </gazebo>
  <gazebo reference="base3__INPUT_INTERFACE">
    <material>Gazebo/Red</material>
    <static>false</static>
    <selfCollide>true</selfCollide>
  </gazebo>
  <gazebo reference="shoulder3__INPUT_INTERFACE">
    <material>Gazebo/Grey</material>
    <static>false</static>
    <selfCollide>true</selfCollide>
  </gazebo>
  <gazebo reference="elbow3__INPUT_INTERFACE">
    <static>false</static>
    <selfCollide>true</selfCollide>
  </gazebo>
  <gazebo reference="leg3__LAST_LINK">
    <material>Gazebo/Grey</material>
    <mu1>0.9</mu1>
    <mu2>0.9</mu2>
    <static>false</static>
    <selfCollide>true</selfCollide>
  </gazebo>
  <gazebo reference="base4__INPUT_INTERFACE">
    <material>Gazebo/Red</material>
    <static>false</static>
    <selfCollide>true</selfCollide>
  </gazebo>
  <gazebo reference="shoulder4__INPUT_INTERFACE">
    <material>Gazebo/Grey</material>
    <static>false</static>
    <selfCollide>true</selfCollide>
  </gazebo>
  <gazebo reference="elbow4__INPUT_INTERFACE">
    <static>false</static>
    <selfCollide>true</selfCollide>
  </gazebo>
  <gazebo reference="leg4__LAST_LINK">
    <material>Gazebo/Grey</material>
    <mu1>0.9</mu1>
    <mu2>0.9</mu2>
    <static>false</static>
    <selfCollide>true</selfCollide>
  </gazebo>
  <gazebo reference="base5__INPUT_INTERFACE">
    <material>Gazebo/Red</material>
    <static>false</static>
    <selfCollide>true</selfCollide>
  </gazebo>
  <gazebo reference="shoulder5__INPUT_INTERFACE">
    <material>Gazebo/Grey</material>
    <static>false</static>
    <selfCollide>true</selfCollide>
  </gazebo>
  <gazebo reference="elbow5__INPUT_INTERFACE">
    <static>false</static>
    <selfCollide>true</selfCollide>
  </gazebo>
  <gazebo reference="leg5__LAST_LINK">
    <material>Gazebo/Grey</material>
    <mu1>0.9</mu1>
    <mu2>0.9</mu2>
    <static>false</static>
    <selfCollide>true</selfCollide>
  </gazebo>
  <gazebo reference="base6__INPUT_INTERFACE">
    <material>Gazebo/Red</material>
    <static>false</static>
    <selfCollide>true</selfCollide>
  </gazebo>
  <gazebo reference="shoulder6__INPUT_INTERFACE">
    <material>Gazebo/Grey</material>
    <static>false</static>
    <selfCollide>true</selfCollide>
  </gazebo>
  <gazebo reference="elbow6__INPUT_INTERFACE">
    <static>false</static>
    <selfCollide>true</selfCollide>
  </gazebo>
  <gazebo reference="leg6__LAST_LINK">
    <material>Gazebo/Grey</material>
    <mu1>0.9</mu1>
    <mu2>0.9</mu2>
    <static>false</static>
    <selfCollide>true</selfCollide>
  </gazebo>
  <gazebo reference="base1">
    <provideFeedback>true</provideFeedback>
  </gazebo>
  <!-- joint_torque_sensor plugin -->
  <gazebo>
    <plugin filename="libgazebo_ros_ft_sensor.so" name="base1_ros_ft_sensor">
      <robotNamespace>/m6</robotNamespace>
      <updateRate>200.0</updateRate>
      <gaussianNoise>0.025</gaussianNoise>
      <topicName>sensors/base1/torque</topicName>
      <jointName>base1</jointName>
    </plugin>
  </gazebo>
  <gazebo reference="shoulder1">
    <provideFeedback>true</provideFeedback>
  </gazebo>
  <!-- joint_torque_sensor plugin -->
  <gazebo>
    <plugin filename="libgazebo_ros_ft_sensor.so" name="shoulder1_ros_ft_sensor">
      <robotNamespace>/m6</robotNamespace>
      <updateRate>200.0</updateRate>
      <gaussianNoise>0.025</gaussianNoise>
      <topicName>sensors/shoulder1/torque</topicName>
      <jointName>shoulder1</jointName>
    </plugin>
  </gazebo>
  <gazebo reference="elbow1">
    <provideFeedback>true</provideFeedback>
  </gazebo>
  <!-- joint_torque_sensor plugin -->
  <gazebo>
    <plugin filename="libgazebo_ros_ft_sensor.so" name="elbow1_ros_ft_sensor">
      <robotNamespace>/m6</robotNamespace>
      <updateRate>200.0</updateRate>
      <gaussianNoise>0.025</gaussianNoise>
      <topicName>sensors/elbow1/torque</topicName>
      <jointName>elbow1</jointName>
    </plugin>
  </gazebo>
  <gazebo reference="base2">
    <provideFeedback>true</provideFeedback>
  </gazebo>
  <!-- joint_torque_sensor plugin -->
  <gazebo>
    <plugin filename="libgazebo_ros_ft_sensor.so" name="base2_ros_ft_sensor">
      <robotNamespace>/m6</robotNamespace>
      <updateRate>200.0</updateRate>
      <gaussianNoise>0.025</gaussianNoise>
      <topicName>sensors/base2/torque</topicName>
      <jointName>base2</jointName>
    </plugin>
  </gazebo>
  <gazebo reference="shoulder2">
    <provideFeedback>true</provideFeedback>
  </gazebo>
  <!-- joint_torque_sensor plugin -->
  <gazebo>
    <plugin filename="libgazebo_ros_ft_sensor.so" name="shoulder2_ros_ft_sensor">
      <robotNamespace>/m6</robotNamespace>
      <updateRate>200.0</updateRate>
      <gaussianNoise>0.025</gaussianNoise>
      <topicName>sensors/shoulder2/torque</topicName>
      <jointName>shoulder2</jointName>
    </plugin>
  </gazebo>
  <gazebo reference="elbow2">
    <provideFeedback>true</provideFeedback>
  </gazebo>
  <!-- joint_torque_sensor plugin -->
  <gazebo>
    <plugin filename="libgazebo_ros_ft_sensor.so" name="elbow2_ros_ft_sensor">
      <robotNamespace>/m6</robotNamespace>
      <updateRate>200.0</updateRate>
      <gaussianNoise>0.025</gaussianNoise>
      <topicName>sensors/elbow2/torque</topicName>
      <jointName>elbow2</jointName>
    </plugin>
  </gazebo>
  <gazebo reference="base3">
    <provideFeedback>true</provideFeedback>
  </gazebo>
  <!-- joint_torque_sensor plugin -->
  <gazebo>
    <plugin filename="libgazebo_ros_ft_sensor.so" name="base3_ros_ft_sensor">
      <robotNamespace>/m6</robotNamespace>
      <updateRate>200.0</updateRate>
      <gaussianNoise>0.025</gaussianNoise>
      <topicName>sensors/base3/torque</topicName>
      <jointName>base3</jointName>
    </plugin>
  </gazebo>
  <gazebo reference="shoulder3">
    <provideFeedback>true</provideFeedback>
  </gazebo>
  <!-- joint_torque_sensor plugin -->
  <gazebo>
    <plugin filename="libgazebo_ros_ft_sensor.so" name="shoulder3_ros_ft_sensor">
      <robotNamespace>/m6</robotNamespace>
      <updateRate>200.0</updateRate>
      <gaussianNoise>0.025</gaussianNoise>
      <topicName>sensors/shoulder3/torque</topicName>
      <jointName>shoulder3</jointName>
    </plugin>
  </gazebo>
  <gazebo reference="elbow3">
    <provideFeedback>true</provideFeedback>
  </gazebo>
  <!-- joint_torque_sensor plugin -->
  <gazebo>
    <plugin filename="libgazebo_ros_ft_sensor.so" name="elbow3_ros_ft_sensor">
      <robotNamespace>/m6</robotNamespace>
      <updateRate>200.0</updateRate>
      <gaussianNoise>0.025</gaussianNoise>
      <topicName>sensors/elbow3/torque</topicName>
      <jointName>elbow3</jointName>
    </plugin>
  </gazebo>
  <gazebo reference="base4">
    <provideFeedback>true</provideFeedback>
  </gazebo>
  <!-- joint_torque_sensor plugin -->
  <gazebo>
    <plugin filename="libgazebo_ros_ft_sensor.so" name="base4_ros_ft_sensor">
      <robotNamespace>/m6</robotNamespace>
      <updateRate>200.0</updateRate>
      <gaussianNoise>0.025</gaussianNoise>
      <topicName>sensors/base4/torque</topicName>
      <jointName>base4</jointName>
    </plugin>
  </gazebo>
  <gazebo reference="shoulder4">
    <provideFeedback>true</provideFeedback>
  </gazebo>
  <!-- joint_torque_sensor plugin -->
  <gazebo>
    <plugin filename="libgazebo_ros_ft_sensor.so" name="shoulder4_ros_ft_sensor">
      <robotNamespace>/m6</robotNamespace>
      <updateRate>200.0</updateRate>
      <gaussianNoise>0.025</gaussianNoise>
      <topicName>sensors/shoulder4/torque</topicName>
      <jointName>shoulder4</jointName>
    </plugin>
  </gazebo>
  <gazebo reference="elbow4">
    <provideFeedback>true</provideFeedback>
  </gazebo>
  <!-- joint_torque_sensor plugin -->
  <gazebo>
    <plugin filename="libgazebo_ros_ft_sensor.so" name="elbow4_ros_ft_sensor">
      <robotNamespace>/m6</robotNamespace>
      <updateRate>200.0</updateRate>
      <gaussianNoise>0.025</gaussianNoise>
      <topicName>sensors/elbow4/torque</topicName>
      <jointName>elbow4</jointName>
    </plugin>
  </gazebo>
  <gazebo reference="base5">
    <provideFeedback>true</provideFeedback>
  </gazebo>
  <!-- joint_torque_sensor plugin -->
  <gazebo>
    <plugin filename="libgazebo_ros_ft_sensor.so" name="base5_ros_ft_sensor">
      <robotNamespace>/m6</robotNamespace>
      <updateRate>200.0</updateRate>
      <gaussianNoise>0.025</gaussianNoise>
      <topicName>sensors/base5/torque</topicName>
      <jointName>base5</jointName>
    </plugin>
  </gazebo>
  <gazebo reference="shoulder5">
    <provideFeedback>true</provideFeedback>
  </gazebo>
  <!-- joint_torque_sensor plugin -->
  <gazebo>
    <plugin filename="libgazebo_ros_ft_sensor.so" name="shoulder5_ros_ft_sensor">
      <robotNamespace>/m6</robotNamespace>
      <updateRate>200.0</updateRate>
      <gaussianNoise>0.025</gaussianNoise>
      <topicName>sensors/shoulder5/torque</topicName>
      <jointName>shoulder5</jointName>
    </plugin>
  </gazebo>
  <gazebo reference="elbow5">
    <provideFeedback>true</provideFeedback>
  </gazebo>
  <!-- joint_torque_sensor plugin -->
  <gazebo>
    <plugin filename="libgazebo_ros_ft_sensor.so" name="elbow5_ros_ft_sensor">
      <robotNamespace>/m6</robotNamespace>
      <updateRate>200.0</updateRate>
      <gaussianNoise>0.025</gaussianNoise>
      <topicName>sensors/elbow5/torque</topicName>
      <jointName>elbow5</jointName>
    </plugin>
  </gazebo>
  <gazebo reference="base6">
    <provideFeedback>true</provideFeedback>
  </gazebo>
  <!-- joint_torque_sensor plugin -->
  <gazebo>
    <plugin filename="libgazebo_ros_ft_sensor.so" name="base6_ros_ft_sensor">
      <robotNamespace>/m6</robotNamespace>
      <updateRate>200.0</updateRate>
      <gaussianNoise>0.025</gaussianNoise>
      <topicName>sensors/base6/torque</topicName>
      <jointName>base6</jointName>
    </plugin>
  </gazebo>
  <gazebo reference="shoulder6">
    <provideFeedback>true</provideFeedback>
  </gazebo>
  <!-- joint_torque_sensor plugin -->
  <gazebo>
    <plugin filename="libgazebo_ros_ft_sensor.so" name="shoulder6_ros_ft_sensor">
      <robotNamespace>/m6</robotNamespace>
      <updateRate>200.0</updateRate>
      <gaussianNoise>0.025</gaussianNoise>
      <topicName>sensors/shoulder6/torque</topicName>
      <jointName>shoulder6</jointName>
    </plugin>
  </gazebo>
  <gazebo reference="elbow6">
    <provideFeedback>true</provideFeedback>
  </gazebo>
  <!-- joint_torque_sensor plugin -->
  <gazebo>
    <plugin filename="libgazebo_ros_ft_sensor.so" name="elbow6_ros_ft_sensor">
      <robotNamespace>/m6</robotNamespace>
      <updateRate>200.0</updateRate>
      <gaussianNoise>0.025</gaussianNoise>
      <topicName>sensors/elbow6/torque</topicName>
      <jointName>elbow6</jointName>
    </plugin>
  </gazebo>
  <gazebo>
    <plugin filename="libgazebo_ros_p3d.so" name="p3d">
      <alwaysOn>true</alwaysOn>
      <updateRate>1000.0</updateRate>
      <bodyName>base_link</bodyName>
      <topicName>nav_msgs</topicName>
      <frameName>world</frameName>
      <xyzOffsets>0 0 0.0</xyzOffsets>
      <rpyOffsets>0 0 0.0</rpyOffsets>
    </plugin>
  </gazebo>
</robot>
