<?xml version="1.0" encoding="utf-8"?>
<!-- =================================================================================== -->
<!-- |    This document was autogenerated by xacro from sea_snake.urdf.xacro           | -->
<!-- |    EDITING THIS FILE BY HAND IS NOT RECOMMENDED                                 | -->
<!-- =================================================================================== -->
<robot name="snake">
  <!-- base body -->
  <link name="link0"/>
  <!-- leg outputs on the base -->
  <joint name="head__OUTPUT_INTERFACE" type="fixed">
    <parent link="link0"/>
    <child link="joint1__INPUT_INTERFACE"/>
    <origin rpy="0 0 1.57079632679" xyz="0 0 0"/>
  </joint>
  <link name="joint1__INPUT_INTERFACE">
    <visual>
      <origin rpy="-1.57075 0 0" xyz="0 0 -0.035"/>
      <geometry>
        <mesh filename="package://reusnake_visualize/meshes/rotary_input.stl"/>
      </geometry>
      <material name="red">
        <color rgba=".82 0.06 0.06 1"/>
      </material>
    </visual>
    <collision>
      <origin rpy="0 0 0" xyz="0 0 -0.0183"/>
      <geometry>
        <cylinder length="-0.033" radius="0.026"/>
      </geometry>
    </collision>
    <inertial>
      <origin rpy="0 0 0" xyz="0 0 -0.0366"/>
      <mass value="0.103"/>
      <inertia ixx="5.4796e-05" ixy="0" ixz="0" iyy="5.4796e-05" iyz="0" izz="3.4814e-05"/>
    </inertial>
  </link>
  <link name="joint1__INPUT_INTERFACE__COLLAR">
    <visual>
      <origin rpy="0 0 0" xyz="0 0 0.005"/>
      <geometry>
        <cylinder length="0.01" radius="0.026"/>
      </geometry>
      <material name="black">
        <color rgba="0 0 0 1"/>
      </material>
    </visual>
  </link>
  <joint name="joint1__INPUT_INTERFACE__COLLAR_JOINT" type="fixed">
    <parent link="joint1__INPUT_INTERFACE"/>
    <child link="joint1__INPUT_INTERFACE__COLLAR"/>
  </joint>
  <joint name="joint1" type="revolute">
    <parent link="joint1__INPUT_INTERFACE"/>
    <child link="joint1__OUTPUT_BODY"/>
    <origin rpy="0 0 0" xyz="0 0 -0.0366"/>
    <axis xyz="0 1 0"/>
    <dynamics damping=".1" friction="0.2"/>
    <limit effort="7.0" lower="-1.57" upper="1.57" velocity="2.208932"/>
  </joint>
  <transmission name="joint1_trans">
    <type>transmission_interface/SimpleTransmission</type>
    <joint name="joint1">
      <hardwareInterface>EffortJointInterface</hardwareInterface>
    </joint>
    <actuator name="joint1_motor">
      <hardwareInterface>EffortJointInterface</hardwareInterface>
      <mechanicalReduction>300</mechanicalReduction>
    </actuator>
  </transmission>
  <link name="joint1__OUTPUT_BODY">
    <visual>
      <origin rpy="-1.57075 0 0" xyz="0 0 0"/>
      <geometry>
        <mesh filename="package://reusnake_visualize/meshes/rotary_output.stl"/>
        <!-- <cylinder radius=".0025" length=".1" /> -->
      </geometry>
      <material name="red">
        <color rgba=".82 0.06 0.06 1"/>
      </material>
    </visual>
    <collision>
      <origin rpy="0 0 0" xyz="0 0 -0.0183"/>
      <geometry>
        <cylinder length="-0.033" radius="0.026"/>
      </geometry>
    </collision>
    <inertial>
      <origin rpy="0 0 0" xyz="0 0 0"/>
      <mass value="0.103"/>
      <inertia ixx="5.4796e-05" ixy="0" ixz="0" iyy="5.4796e-05" iyz="0" izz="3.4814e-05"/>
    </inertial>
  </link>
  <joint name="joint1__OUTPUT_INTERFACE" type="fixed">
    <parent link="joint1__OUTPUT_BODY"/>
    <child link="joint2__INPUT_INTERFACE"/>
    <origin rpy="0 0 -1.57075" xyz="0 0 -0.0273"/>
  </joint>
  <link name="joint2__INPUT_INTERFACE">
    <visual>
      <origin rpy="-1.57075 0 0" xyz="0 0 -0.035"/>
      <geometry>
        <mesh filename="package://reusnake_visualize/meshes/rotary_input.stl"/>
      </geometry>
      <material name="red">
        <color rgba=".82 0.06 0.06 1"/>
      </material>
    </visual>
    <collision>
      <origin rpy="0 0 0" xyz="0 0 -0.0183"/>
      <geometry>
        <cylinder length="-0.033" radius="0.026"/>
      </geometry>
    </collision>
    <inertial>
      <origin rpy="0 0 0" xyz="0 0 -0.0366"/>
      <mass value="0.103"/>
      <inertia ixx="5.4796e-05" ixy="0" ixz="0" iyy="5.4796e-05" iyz="0" izz="3.4814e-05"/>
    </inertial>
  </link>
  <link name="joint2__INPUT_INTERFACE__COLLAR">
    <visual>
      <origin rpy="0 0 0" xyz="0 0 0.005"/>
      <geometry>
        <cylinder length="0.01" radius="0.026"/>
      </geometry>
      <material name="black">
        <color rgba="0 0 0 1"/>
      </material>
    </visual>
  </link>
  <joint name="joint2__INPUT_INTERFACE__COLLAR_JOINT" type="fixed">
    <parent link="joint2__INPUT_INTERFACE"/>
    <child link="joint2__INPUT_INTERFACE__COLLAR"/>
  </joint>
  <joint name="joint2" type="revolute">
    <parent link="joint2__INPUT_INTERFACE"/>
    <child link="joint2__OUTPUT_BODY"/>
    <origin rpy="0 0 0" xyz="0 0 -0.0366"/>
    <axis xyz="0 1 0"/>
    <dynamics damping=".1" friction="0.2"/>
    <limit effort="7.0" lower="-1.57" upper="1.57" velocity="2.208932"/>
  </joint>
  <transmission name="joint2_trans">
    <type>transmission_interface/SimpleTransmission</type>
    <joint name="joint2">
      <hardwareInterface>EffortJointInterface</hardwareInterface>
    </joint>
    <actuator name="joint2_motor">
      <hardwareInterface>EffortJointInterface</hardwareInterface>
      <mechanicalReduction>300</mechanicalReduction>
    </actuator>
  </transmission>
  <link name="joint2__OUTPUT_BODY">
    <visual>
      <origin rpy="-1.57075 0 0" xyz="0 0 0"/>
      <geometry>
        <mesh filename="package://reusnake_visualize/meshes/rotary_output.stl"/>
        <!-- <cylinder radius=".0025" length=".1" /> -->
      </geometry>
      <material name="red">
        <color rgba=".82 0.06 0.06 1"/>
      </material>
    </visual>
    <collision>
      <origin rpy="0 0 0" xyz="0 0 -0.0183"/>
      <geometry>
        <cylinder length="-0.033" radius="0.026"/>
      </geometry>
    </collision>
    <inertial>
      <origin rpy="0 0 0" xyz="0 0 0"/>
      <mass value="0.103"/>
      <inertia ixx="5.4796e-05" ixy="0" ixz="0" iyy="5.4796e-05" iyz="0" izz="3.4814e-05"/>
    </inertial>
  </link>
  <joint name="joint2__OUTPUT_INTERFACE" type="fixed">
    <parent link="joint2__OUTPUT_BODY"/>
    <child link="joint3__INPUT_INTERFACE"/>
    <origin rpy="0 0 -1.57075" xyz="0 0 -0.0273"/>
  </joint>
  <link name="joint3__INPUT_INTERFACE">
    <visual>
      <origin rpy="-1.57075 0 0" xyz="0 0 -0.035"/>
      <geometry>
        <mesh filename="package://reusnake_visualize/meshes/rotary_input.stl"/>
      </geometry>
      <material name="red">
        <color rgba=".82 0.06 0.06 1"/>
      </material>
    </visual>
    <collision>
      <origin rpy="0 0 0" xyz="0 0 -0.0183"/>
      <geometry>
        <cylinder length="-0.033" radius="0.026"/>
      </geometry>
    </collision>
    <inertial>
      <origin rpy="0 0 0" xyz="0 0 -0.0366"/>
      <mass value="0.103"/>
      <inertia ixx="5.4796e-05" ixy="0" ixz="0" iyy="5.4796e-05" iyz="0" izz="3.4814e-05"/>
    </inertial>
  </link>
  <link name="joint3__INPUT_INTERFACE__COLLAR">
    <visual>
      <origin rpy="0 0 0" xyz="0 0 0.005"/>
      <geometry>
        <cylinder length="0.01" radius="0.026"/>
      </geometry>
      <material name="black">
        <color rgba="0 0 0 1"/>
      </material>
    </visual>
  </link>
  <joint name="joint3__INPUT_INTERFACE__COLLAR_JOINT" type="fixed">
    <parent link="joint3__INPUT_INTERFACE"/>
    <child link="joint3__INPUT_INTERFACE__COLLAR"/>
  </joint>
  <joint name="joint3" type="revolute">
    <parent link="joint3__INPUT_INTERFACE"/>
    <child link="joint3__OUTPUT_BODY"/>
    <origin rpy="0 0 0" xyz="0 0 -0.0366"/>
    <axis xyz="0 1 0"/>
    <dynamics damping=".1" friction="0.2"/>
    <limit effort="7.0" lower="-1.57" upper="1.57" velocity="2.208932"/>
  </joint>
  <transmission name="joint3_trans">
    <type>transmission_interface/SimpleTransmission</type>
    <joint name="joint3">
      <hardwareInterface>EffortJointInterface</hardwareInterface>
    </joint>
    <actuator name="joint3_motor">
      <hardwareInterface>EffortJointInterface</hardwareInterface>
      <mechanicalReduction>300</mechanicalReduction>
    </actuator>
  </transmission>
  <link name="joint3__OUTPUT_BODY">
    <visual>
      <origin rpy="-1.57075 0 0" xyz="0 0 0"/>
      <geometry>
        <mesh filename="package://reusnake_visualize/meshes/rotary_output.stl"/>
        <!-- <cylinder radius=".0025" length=".1" /> -->
      </geometry>
      <material name="red">
        <color rgba=".82 0.06 0.06 1"/>
      </material>
    </visual>
    <collision>
      <origin rpy="0 0 0" xyz="0 0 -0.0183"/>
      <geometry>
        <cylinder length="-0.033" radius="0.026"/>
      </geometry>
    </collision>
    <inertial>
      <origin rpy="0 0 0" xyz="0 0 0"/>
      <mass value="0.103"/>
      <inertia ixx="5.4796e-05" ixy="0" ixz="0" iyy="5.4796e-05" iyz="0" izz="3.4814e-05"/>
    </inertial>
  </link>
  <joint name="joint3__OUTPUT_INTERFACE" type="fixed">
    <parent link="joint3__OUTPUT_BODY"/>
    <child link="joint4__INPUT_INTERFACE"/>
    <origin rpy="0 0 -1.57075" xyz="0 0 -0.0273"/>
  </joint>
  <link name="joint4__INPUT_INTERFACE">
    <visual>
      <origin rpy="-1.57075 0 0" xyz="0 0 -0.035"/>
      <geometry>
        <mesh filename="package://reusnake_visualize/meshes/rotary_input.stl"/>
      </geometry>
      <material name="red">
        <color rgba=".82 0.06 0.06 1"/>
      </material>
    </visual>
    <collision>
      <origin rpy="0 0 0" xyz="0 0 -0.0183"/>
      <geometry>
        <cylinder length="-0.033" radius="0.026"/>
      </geometry>
    </collision>
    <inertial>
      <origin rpy="0 0 0" xyz="0 0 -0.0366"/>
      <mass value="0.103"/>
      <inertia ixx="5.4796e-05" ixy="0" ixz="0" iyy="5.4796e-05" iyz="0" izz="3.4814e-05"/>
    </inertial>
  </link>
  <link name="joint4__INPUT_INTERFACE__COLLAR">
    <visual>
      <origin rpy="0 0 0" xyz="0 0 0.005"/>
      <geometry>
        <cylinder length="0.01" radius="0.026"/>
      </geometry>
      <material name="black">
        <color rgba="0 0 0 1"/>
      </material>
    </visual>
  </link>
  <joint name="joint4__INPUT_INTERFACE__COLLAR_JOINT" type="fixed">
    <parent link="joint4__INPUT_INTERFACE"/>
    <child link="joint4__INPUT_INTERFACE__COLLAR"/>
  </joint>
  <joint name="joint4" type="revolute">
    <parent link="joint4__INPUT_INTERFACE"/>
    <child link="joint4__OUTPUT_BODY"/>
    <origin rpy="0 0 0" xyz="0 0 -0.0366"/>
    <axis xyz="0 1 0"/>
    <dynamics damping=".1" friction="0.2"/>
    <limit effort="7.0" lower="-1.57" upper="1.57" velocity="2.208932"/>
  </joint>
  <transmission name="joint4_trans">
    <type>transmission_interface/SimpleTransmission</type>
    <joint name="joint4">
      <hardwareInterface>EffortJointInterface</hardwareInterface>
    </joint>
    <actuator name="joint4_motor">
      <hardwareInterface>EffortJointInterface</hardwareInterface>
      <mechanicalReduction>300</mechanicalReduction>
    </actuator>
  </transmission>
  <link name="joint4__OUTPUT_BODY">
    <visual>
      <origin rpy="-1.57075 0 0" xyz="0 0 0"/>
      <geometry>
        <mesh filename="package://reusnake_visualize/meshes/rotary_output.stl"/>
        <!-- <cylinder radius=".0025" length=".1" /> -->
      </geometry>
      <material name="red">
        <color rgba=".82 0.06 0.06 1"/>
      </material>
    </visual>
    <collision>
      <origin rpy="0 0 0" xyz="0 0 -0.0183"/>
      <geometry>
        <cylinder length="-0.033" radius="0.026"/>
      </geometry>
    </collision>
    <inertial>
      <origin rpy="0 0 0" xyz="0 0 0"/>
      <mass value="0.103"/>
      <inertia ixx="5.4796e-05" ixy="0" ixz="0" iyy="5.4796e-05" iyz="0" izz="3.4814e-05"/>
    </inertial>
  </link>
  <joint name="joint4__OUTPUT_INTERFACE" type="fixed">
    <parent link="joint4__OUTPUT_BODY"/>
    <child link="joint5__INPUT_INTERFACE"/>
    <origin rpy="0 0 -1.57075" xyz="0 0 -0.0273"/>
  </joint>
  <link name="joint5__INPUT_INTERFACE">
    <visual>
      <origin rpy="-1.57075 0 0" xyz="0 0 -0.035"/>
      <geometry>
        <mesh filename="package://reusnake_visualize/meshes/rotary_input.stl"/>
      </geometry>
      <material name="red">
        <color rgba=".82 0.06 0.06 1"/>
      </material>
    </visual>
    <collision>
      <origin rpy="0 0 0" xyz="0 0 -0.0183"/>
      <geometry>
        <cylinder length="-0.033" radius="0.026"/>
      </geometry>
    </collision>
    <inertial>
      <origin rpy="0 0 0" xyz="0 0 -0.0366"/>
      <mass value="0.103"/>
      <inertia ixx="5.4796e-05" ixy="0" ixz="0" iyy="5.4796e-05" iyz="0" izz="3.4814e-05"/>
    </inertial>
  </link>
  <link name="joint5__INPUT_INTERFACE__COLLAR">
    <visual>
      <origin rpy="0 0 0" xyz="0 0 0.005"/>
      <geometry>
        <cylinder length="0.01" radius="0.026"/>
      </geometry>
      <material name="black">
        <color rgba="0 0 0 1"/>
      </material>
    </visual>
  </link>
  <joint name="joint5__INPUT_INTERFACE__COLLAR_JOINT" type="fixed">
    <parent link="joint5__INPUT_INTERFACE"/>
    <child link="joint5__INPUT_INTERFACE__COLLAR"/>
  </joint>
  <joint name="joint5" type="revolute">
    <parent link="joint5__INPUT_INTERFACE"/>
    <child link="joint5__OUTPUT_BODY"/>
    <origin rpy="0 0 0" xyz="0 0 -0.0366"/>
    <axis xyz="0 1 0"/>
    <dynamics damping=".1" friction="0.2"/>
    <limit effort="7.0" lower="-1.57" upper="1.57" velocity="2.208932"/>
  </joint>
  <transmission name="joint5_trans">
    <type>transmission_interface/SimpleTransmission</type>
    <joint name="joint5">
      <hardwareInterface>EffortJointInterface</hardwareInterface>
    </joint>
    <actuator name="joint5_motor">
      <hardwareInterface>EffortJointInterface</hardwareInterface>
      <mechanicalReduction>300</mechanicalReduction>
    </actuator>
  </transmission>
  <link name="joint5__OUTPUT_BODY">
    <visual>
      <origin rpy="-1.57075 0 0" xyz="0 0 0"/>
      <geometry>
        <mesh filename="package://reusnake_visualize/meshes/rotary_output.stl"/>
        <!-- <cylinder radius=".0025" length=".1" /> -->
      </geometry>
      <material name="red">
        <color rgba=".82 0.06 0.06 1"/>
      </material>
    </visual>
    <collision>
      <origin rpy="0 0 0" xyz="0 0 -0.0183"/>
      <geometry>
        <cylinder length="-0.033" radius="0.026"/>
      </geometry>
    </collision>
    <inertial>
      <origin rpy="0 0 0" xyz="0 0 0"/>
      <mass value="0.103"/>
      <inertia ixx="5.4796e-05" ixy="0" ixz="0" iyy="5.4796e-05" iyz="0" izz="3.4814e-05"/>
    </inertial>
  </link>
  <joint name="joint5__OUTPUT_INTERFACE" type="fixed">
    <parent link="joint5__OUTPUT_BODY"/>
    <child link="joint6__INPUT_INTERFACE"/>
    <origin rpy="0 0 -1.57075" xyz="0 0 -0.0273"/>
  </joint>
  <link name="joint6__INPUT_INTERFACE">
    <visual>
      <origin rpy="-1.57075 0 0" xyz="0 0 -0.035"/>
      <geometry>
        <mesh filename="package://reusnake_visualize/meshes/rotary_input.stl"/>
      </geometry>
      <material name="red">
        <color rgba=".82 0.06 0.06 1"/>
      </material>
    </visual>
    <collision>
      <origin rpy="0 0 0" xyz="0 0 -0.0183"/>
      <geometry>
        <cylinder length="-0.033" radius="0.026"/>
      </geometry>
    </collision>
    <inertial>
      <origin rpy="0 0 0" xyz="0 0 -0.0366"/>
      <mass value="0.103"/>
      <inertia ixx="5.4796e-05" ixy="0" ixz="0" iyy="5.4796e-05" iyz="0" izz="3.4814e-05"/>
    </inertial>
  </link>
  <link name="joint6__INPUT_INTERFACE__COLLAR">
    <visual>
      <origin rpy="0 0 0" xyz="0 0 0.005"/>
      <geometry>
        <cylinder length="0.01" radius="0.026"/>
      </geometry>
      <material name="black">
        <color rgba="0 0 0 1"/>
      </material>
    </visual>
  </link>
  <joint name="joint6__INPUT_INTERFACE__COLLAR_JOINT" type="fixed">
    <parent link="joint6__INPUT_INTERFACE"/>
    <child link="joint6__INPUT_INTERFACE__COLLAR"/>
  </joint>
  <joint name="joint6" type="revolute">
    <parent link="joint6__INPUT_INTERFACE"/>
    <child link="joint6__OUTPUT_BODY"/>
    <origin rpy="0 0 0" xyz="0 0 -0.0366"/>
    <axis xyz="0 1 0"/>
    <dynamics damping=".1" friction="0.2"/>
    <limit effort="7.0" lower="-1.57" upper="1.57" velocity="2.208932"/>
  </joint>
  <transmission name="joint6_trans">
    <type>transmission_interface/SimpleTransmission</type>
    <joint name="joint6">
      <hardwareInterface>EffortJointInterface</hardwareInterface>
    </joint>
    <actuator name="joint6_motor">
      <hardwareInterface>EffortJointInterface</hardwareInterface>
      <mechanicalReduction>300</mechanicalReduction>
    </actuator>
  </transmission>
  <link name="joint6__OUTPUT_BODY">
    <visual>
      <origin rpy="-1.57075 0 0" xyz="0 0 0"/>
      <geometry>
        <mesh filename="package://reusnake_visualize/meshes/rotary_output.stl"/>
        <!-- <cylinder radius=".0025" length=".1" /> -->
      </geometry>
      <material name="red">
        <color rgba=".82 0.06 0.06 1"/>
      </material>
    </visual>
    <collision>
      <origin rpy="0 0 0" xyz="0 0 -0.0183"/>
      <geometry>
        <cylinder length="-0.033" radius="0.026"/>
      </geometry>
    </collision>
    <inertial>
      <origin rpy="0 0 0" xyz="0 0 0"/>
      <mass value="0.103"/>
      <inertia ixx="5.4796e-05" ixy="0" ixz="0" iyy="5.4796e-05" iyz="0" izz="3.4814e-05"/>
    </inertial>
  </link>
  <joint name="joint6__OUTPUT_INTERFACE" type="fixed">
    <parent link="joint6__OUTPUT_BODY"/>
    <child link="joint7__INPUT_INTERFACE"/>
    <origin rpy="0 0 -1.57075" xyz="0 0 -0.0273"/>
  </joint>
  <link name="joint7__INPUT_INTERFACE">
    <visual>
      <origin rpy="-1.57075 0 0" xyz="0 0 -0.035"/>
      <geometry>
        <mesh filename="package://reusnake_visualize/meshes/rotary_input.stl"/>
      </geometry>
      <material name="red">
        <color rgba=".82 0.06 0.06 1"/>
      </material>
    </visual>
    <collision>
      <origin rpy="0 0 0" xyz="0 0 -0.0183"/>
      <geometry>
        <cylinder length="-0.033" radius="0.026"/>
      </geometry>
    </collision>
    <inertial>
      <origin rpy="0 0 0" xyz="0 0 -0.0366"/>
      <mass value="0.103"/>
      <inertia ixx="5.4796e-05" ixy="0" ixz="0" iyy="5.4796e-05" iyz="0" izz="3.4814e-05"/>
    </inertial>
  </link>
  <link name="joint7__INPUT_INTERFACE__COLLAR">
    <visual>
      <origin rpy="0 0 0" xyz="0 0 0.005"/>
      <geometry>
        <cylinder length="0.01" radius="0.026"/>
      </geometry>
      <material name="black">
        <color rgba="0 0 0 1"/>
      </material>
    </visual>
  </link>
  <joint name="joint7__INPUT_INTERFACE__COLLAR_JOINT" type="fixed">
    <parent link="joint7__INPUT_INTERFACE"/>
    <child link="joint7__INPUT_INTERFACE__COLLAR"/>
  </joint>
  <joint name="joint7" type="revolute">
    <parent link="joint7__INPUT_INTERFACE"/>
    <child link="joint7__OUTPUT_BODY"/>
    <origin rpy="0 0 0" xyz="0 0 -0.0366"/>
    <axis xyz="0 1 0"/>
    <dynamics damping=".1" friction="0.2"/>
    <limit effort="7.0" lower="-1.57" upper="1.57" velocity="2.208932"/>
  </joint>
  <transmission name="joint7_trans">
    <type>transmission_interface/SimpleTransmission</type>
    <joint name="joint7">
      <hardwareInterface>EffortJointInterface</hardwareInterface>
    </joint>
    <actuator name="joint7_motor">
      <hardwareInterface>EffortJointInterface</hardwareInterface>
      <mechanicalReduction>300</mechanicalReduction>
    </actuator>
  </transmission>
  <link name="joint7__OUTPUT_BODY">
    <visual>
      <origin rpy="-1.57075 0 0" xyz="0 0 0"/>
      <geometry>
        <mesh filename="package://reusnake_visualize/meshes/rotary_output.stl"/>
        <!-- <cylinder radius=".0025" length=".1" /> -->
      </geometry>
      <material name="red">
        <color rgba=".82 0.06 0.06 1"/>
      </material>
    </visual>
    <collision>
      <origin rpy="0 0 0" xyz="0 0 -0.0183"/>
      <geometry>
        <cylinder length="-0.033" radius="0.026"/>
      </geometry>
    </collision>
    <inertial>
      <origin rpy="0 0 0" xyz="0 0 0"/>
      <mass value="0.103"/>
      <inertia ixx="5.4796e-05" ixy="0" ixz="0" iyy="5.4796e-05" iyz="0" izz="3.4814e-05"/>
    </inertial>
  </link>
  <joint name="joint7__OUTPUT_INTERFACE" type="fixed">
    <parent link="joint7__OUTPUT_BODY"/>
    <child link="joint8__INPUT_INTERFACE"/>
    <origin rpy="0 0 -1.57075" xyz="0 0 -0.0273"/>
  </joint>
  <link name="joint8__INPUT_INTERFACE">
    <visual>
      <origin rpy="-1.57075 0 0" xyz="0 0 -0.035"/>
      <geometry>
        <mesh filename="package://reusnake_visualize/meshes/rotary_input.stl"/>
      </geometry>
      <material name="red">
        <color rgba=".82 0.06 0.06 1"/>
      </material>
    </visual>
    <collision>
      <origin rpy="0 0 0" xyz="0 0 -0.0183"/>
      <geometry>
        <cylinder length="-0.033" radius="0.026"/>
      </geometry>
    </collision>
    <inertial>
      <origin rpy="0 0 0" xyz="0 0 -0.0366"/>
      <mass value="0.103"/>
      <inertia ixx="5.4796e-05" ixy="0" ixz="0" iyy="5.4796e-05" iyz="0" izz="3.4814e-05"/>
    </inertial>
  </link>
  <link name="joint8__INPUT_INTERFACE__COLLAR">
    <visual>
      <origin rpy="0 0 0" xyz="0 0 0.005"/>
      <geometry>
        <cylinder length="0.01" radius="0.026"/>
      </geometry>
      <material name="black">
        <color rgba="0 0 0 1"/>
      </material>
    </visual>
  </link>
  <joint name="joint8__INPUT_INTERFACE__COLLAR_JOINT" type="fixed">
    <parent link="joint8__INPUT_INTERFACE"/>
    <child link="joint8__INPUT_INTERFACE__COLLAR"/>
  </joint>
  <joint name="joint8" type="revolute">
    <parent link="joint8__INPUT_INTERFACE"/>
    <child link="joint8__OUTPUT_BODY"/>
    <origin rpy="0 0 0" xyz="0 0 -0.0366"/>
    <axis xyz="0 1 0"/>
    <dynamics damping=".1" friction="0.2"/>
    <limit effort="7.0" lower="-1.57" upper="1.57" velocity="2.208932"/>
  </joint>
  <transmission name="joint8_trans">
    <type>transmission_interface/SimpleTransmission</type>
    <joint name="joint8">
      <hardwareInterface>EffortJointInterface</hardwareInterface>
    </joint>
    <actuator name="joint8_motor">
      <hardwareInterface>EffortJointInterface</hardwareInterface>
      <mechanicalReduction>300</mechanicalReduction>
    </actuator>
  </transmission>
  <link name="joint8__OUTPUT_BODY">
    <visual>
      <origin rpy="-1.57075 0 0" xyz="0 0 0"/>
      <geometry>
        <mesh filename="package://reusnake_visualize/meshes/rotary_output.stl"/>
        <!-- <cylinder radius=".0025" length=".1" /> -->
      </geometry>
      <material name="red">
        <color rgba=".82 0.06 0.06 1"/>
      </material>
    </visual>
    <collision>
      <origin rpy="0 0 0" xyz="0 0 -0.0183"/>
      <geometry>
        <cylinder length="-0.033" radius="0.026"/>
      </geometry>
    </collision>
    <inertial>
      <origin rpy="0 0 0" xyz="0 0 0"/>
      <mass value="0.103"/>
      <inertia ixx="5.4796e-05" ixy="0" ixz="0" iyy="5.4796e-05" iyz="0" izz="3.4814e-05"/>
    </inertial>
  </link>
  <joint name="joint8__OUTPUT_INTERFACE" type="fixed">
    <parent link="joint8__OUTPUT_BODY"/>
    <child link="joint9__INPUT_INTERFACE"/>
    <origin rpy="0 0 -1.57075" xyz="0 0 -0.0273"/>
  </joint>
  <link name="joint9__INPUT_INTERFACE">
    <visual>
      <origin rpy="-1.57075 0 0" xyz="0 0 -0.035"/>
      <geometry>
        <mesh filename="package://reusnake_visualize/meshes/rotary_input.stl"/>
      </geometry>
      <material name="red">
        <color rgba=".82 0.06 0.06 1"/>
      </material>
    </visual>
    <collision>
      <origin rpy="0 0 0" xyz="0 0 -0.0183"/>
      <geometry>
        <cylinder length="-0.033" radius="0.026"/>
      </geometry>
    </collision>
    <inertial>
      <origin rpy="0 0 0" xyz="0 0 -0.0366"/>
      <mass value="0.103"/>
      <inertia ixx="5.4796e-05" ixy="0" ixz="0" iyy="5.4796e-05" iyz="0" izz="3.4814e-05"/>
    </inertial>
  </link>
  <link name="joint9__INPUT_INTERFACE__COLLAR">
    <visual>
      <origin rpy="0 0 0" xyz="0 0 0.005"/>
      <geometry>
        <cylinder length="0.01" radius="0.026"/>
      </geometry>
      <material name="black">
        <color rgba="0 0 0 1"/>
      </material>
    </visual>
  </link>
  <joint name="joint9__INPUT_INTERFACE__COLLAR_JOINT" type="fixed">
    <parent link="joint9__INPUT_INTERFACE"/>
    <child link="joint9__INPUT_INTERFACE__COLLAR"/>
  </joint>
  <joint name="joint9" type="revolute">
    <parent link="joint9__INPUT_INTERFACE"/>
    <child link="joint9__OUTPUT_BODY"/>
    <origin rpy="0 0 0" xyz="0 0 -0.0366"/>
    <axis xyz="0 1 0"/>
    <dynamics damping=".1" friction="0.2"/>
    <limit effort="7.0" lower="-1.57" upper="1.57" velocity="2.208932"/>
  </joint>
  <transmission name="joint9_trans">
    <type>transmission_interface/SimpleTransmission</type>
    <joint name="joint9">
      <hardwareInterface>EffortJointInterface</hardwareInterface>
    </joint>
    <actuator name="joint9_motor">
      <hardwareInterface>EffortJointInterface</hardwareInterface>
      <mechanicalReduction>300</mechanicalReduction>
    </actuator>
  </transmission>
  <link name="joint9__OUTPUT_BODY">
    <visual>
      <origin rpy="-1.57075 0 0" xyz="0 0 0"/>
      <geometry>
        <mesh filename="package://reusnake_visualize/meshes/rotary_output.stl"/>
        <!-- <cylinder radius=".0025" length=".1" /> -->
      </geometry>
      <material name="red">
        <color rgba=".82 0.06 0.06 1"/>
      </material>
    </visual>
    <collision>
      <origin rpy="0 0 0" xyz="0 0 -0.0183"/>
      <geometry>
        <cylinder length="-0.033" radius="0.026"/>
      </geometry>
    </collision>
    <inertial>
      <origin rpy="0 0 0" xyz="0 0 0"/>
      <mass value="0.103"/>
      <inertia ixx="5.4796e-05" ixy="0" ixz="0" iyy="5.4796e-05" iyz="0" izz="3.4814e-05"/>
    </inertial>
  </link>
  <joint name="joint9__OUTPUT_INTERFACE" type="fixed">
    <parent link="joint9__OUTPUT_BODY"/>
    <child link="joint10__INPUT_INTERFACE"/>
    <origin rpy="0 0 -1.57075" xyz="0 0 -0.0273"/>
  </joint>
  <link name="joint10__INPUT_INTERFACE">
    <visual>
      <origin rpy="-1.57075 0 0" xyz="0 0 -0.035"/>
      <geometry>
        <mesh filename="package://reusnake_visualize/meshes/rotary_input.stl"/>
      </geometry>
      <material name="red">
        <color rgba=".82 0.06 0.06 1"/>
      </material>
    </visual>
    <collision>
      <origin rpy="0 0 0" xyz="0 0 -0.0183"/>
      <geometry>
        <cylinder length="-0.033" radius="0.026"/>
      </geometry>
    </collision>
    <inertial>
      <origin rpy="0 0 0" xyz="0 0 -0.0366"/>
      <mass value="0.103"/>
      <inertia ixx="5.4796e-05" ixy="0" ixz="0" iyy="5.4796e-05" iyz="0" izz="3.4814e-05"/>
    </inertial>
  </link>
  <link name="joint10__INPUT_INTERFACE__COLLAR">
    <visual>
      <origin rpy="0 0 0" xyz="0 0 0.005"/>
      <geometry>
        <cylinder length="0.01" radius="0.026"/>
      </geometry>
      <material name="black">
        <color rgba="0 0 0 1"/>
      </material>
    </visual>
  </link>
  <joint name="joint10__INPUT_INTERFACE__COLLAR_JOINT" type="fixed">
    <parent link="joint10__INPUT_INTERFACE"/>
    <child link="joint10__INPUT_INTERFACE__COLLAR"/>
  </joint>
  <joint name="joint10" type="revolute">
    <parent link="joint10__INPUT_INTERFACE"/>
    <child link="joint10__OUTPUT_BODY"/>
    <origin rpy="0 0 0" xyz="0 0 -0.0366"/>
    <axis xyz="0 1 0"/>
    <dynamics damping=".1" friction="0.2"/>
    <limit effort="7.0" lower="-1.57" upper="1.57" velocity="2.208932"/>
  </joint>
  <transmission name="joint10_trans">
    <type>transmission_interface/SimpleTransmission</type>
    <joint name="joint10">
      <hardwareInterface>EffortJointInterface</hardwareInterface>
    </joint>
    <actuator name="joint10_motor">
      <hardwareInterface>EffortJointInterface</hardwareInterface>
      <mechanicalReduction>300</mechanicalReduction>
    </actuator>
  </transmission>
  <link name="joint10__OUTPUT_BODY">
    <visual>
      <origin rpy="-1.57075 0 0" xyz="0 0 0"/>
      <geometry>
        <mesh filename="package://reusnake_visualize/meshes/rotary_output.stl"/>
        <!-- <cylinder radius=".0025" length=".1" /> -->
      </geometry>
      <material name="red">
        <color rgba=".82 0.06 0.06 1"/>
      </material>
    </visual>
    <collision>
      <origin rpy="0 0 0" xyz="0 0 -0.0183"/>
      <geometry>
        <cylinder length="-0.033" radius="0.026"/>
      </geometry>
    </collision>
    <inertial>
      <origin rpy="0 0 0" xyz="0 0 0"/>
      <mass value="0.103"/>
      <inertia ixx="5.4796e-05" ixy="0" ixz="0" iyy="5.4796e-05" iyz="0" izz="3.4814e-05"/>
    </inertial>
  </link>
  <joint name="joint10__OUTPUT_INTERFACE" type="fixed">
    <parent link="joint10__OUTPUT_BODY"/>
    <child link="joint11__INPUT_INTERFACE"/>
    <origin rpy="0 0 -1.57075" xyz="0 0 -0.0273"/>
  </joint>
  <link name="joint11__INPUT_INTERFACE">
    <visual>
      <origin rpy="-1.57075 0 0" xyz="0 0 -0.035"/>
      <geometry>
        <mesh filename="package://reusnake_visualize/meshes/rotary_input.stl"/>
      </geometry>
      <material name="red">
        <color rgba=".82 0.06 0.06 1"/>
      </material>
    </visual>
    <collision>
      <origin rpy="0 0 0" xyz="0 0 -0.0183"/>
      <geometry>
        <cylinder length="-0.033" radius="0.026"/>
      </geometry>
    </collision>
    <inertial>
      <origin rpy="0 0 0" xyz="0 0 -0.0366"/>
      <mass value="0.103"/>
      <inertia ixx="5.4796e-05" ixy="0" ixz="0" iyy="5.4796e-05" iyz="0" izz="3.4814e-05"/>
    </inertial>
  </link>
  <link name="joint11__INPUT_INTERFACE__COLLAR">
    <visual>
      <origin rpy="0 0 0" xyz="0 0 0.005"/>
      <geometry>
        <cylinder length="0.01" radius="0.026"/>
      </geometry>
      <material name="black">
        <color rgba="0 0 0 1"/>
      </material>
    </visual>
  </link>
  <joint name="joint11__INPUT_INTERFACE__COLLAR_JOINT" type="fixed">
    <parent link="joint11__INPUT_INTERFACE"/>
    <child link="joint11__INPUT_INTERFACE__COLLAR"/>
  </joint>
  <joint name="joint11" type="revolute">
    <parent link="joint11__INPUT_INTERFACE"/>
    <child link="joint11__OUTPUT_BODY"/>
    <origin rpy="0 0 0" xyz="0 0 -0.0366"/>
    <axis xyz="0 1 0"/>
    <dynamics damping=".1" friction="0.2"/>
    <limit effort="7.0" lower="-1.57" upper="1.57" velocity="2.208932"/>
  </joint>
  <transmission name="joint11_trans">
    <type>transmission_interface/SimpleTransmission</type>
    <joint name="joint11">
      <hardwareInterface>EffortJointInterface</hardwareInterface>
    </joint>
    <actuator name="joint11_motor">
      <hardwareInterface>EffortJointInterface</hardwareInterface>
      <mechanicalReduction>300</mechanicalReduction>
    </actuator>
  </transmission>
  <link name="joint11__OUTPUT_BODY">
    <visual>
      <origin rpy="-1.57075 0 0" xyz="0 0 0"/>
      <geometry>
        <mesh filename="package://reusnake_visualize/meshes/rotary_output.stl"/>
        <!-- <cylinder radius=".0025" length=".1" /> -->
      </geometry>
      <material name="red">
        <color rgba=".82 0.06 0.06 1"/>
      </material>
    </visual>
    <collision>
      <origin rpy="0 0 0" xyz="0 0 -0.0183"/>
      <geometry>
        <cylinder length="-0.033" radius="0.026"/>
      </geometry>
    </collision>
    <inertial>
      <origin rpy="0 0 0" xyz="0 0 0"/>
      <mass value="0.103"/>
      <inertia ixx="5.4796e-05" ixy="0" ixz="0" iyy="5.4796e-05" iyz="0" izz="3.4814e-05"/>
    </inertial>
  </link>
  <joint name="joint11__OUTPUT_INTERFACE" type="fixed">
    <parent link="joint11__OUTPUT_BODY"/>
    <child link="joint12__INPUT_INTERFACE"/>
    <origin rpy="0 0 -1.57075" xyz="0 0 -0.0273"/>
  </joint>
  <link name="joint12__INPUT_INTERFACE">
    <visual>
      <origin rpy="-1.57075 0 0" xyz="0 0 -0.035"/>
      <geometry>
        <mesh filename="package://reusnake_visualize/meshes/rotary_input.stl"/>
      </geometry>
      <material name="red">
        <color rgba=".82 0.06 0.06 1"/>
      </material>
    </visual>
    <collision>
      <origin rpy="0 0 0" xyz="0 0 -0.0183"/>
      <geometry>
        <cylinder length="-0.033" radius="0.026"/>
      </geometry>
    </collision>
    <inertial>
      <origin rpy="0 0 0" xyz="0 0 -0.0366"/>
      <mass value="0.103"/>
      <inertia ixx="5.4796e-05" ixy="0" ixz="0" iyy="5.4796e-05" iyz="0" izz="3.4814e-05"/>
    </inertial>
  </link>
  <link name="joint12__INPUT_INTERFACE__COLLAR">
    <visual>
      <origin rpy="0 0 0" xyz="0 0 0.005"/>
      <geometry>
        <cylinder length="0.01" radius="0.026"/>
      </geometry>
      <material name="black">
        <color rgba="0 0 0 1"/>
      </material>
    </visual>
  </link>
  <joint name="joint12__INPUT_INTERFACE__COLLAR_JOINT" type="fixed">
    <parent link="joint12__INPUT_INTERFACE"/>
    <child link="joint12__INPUT_INTERFACE__COLLAR"/>
  </joint>
  <joint name="joint12" type="revolute">
    <parent link="joint12__INPUT_INTERFACE"/>
    <child link="joint12__OUTPUT_BODY"/>
    <origin rpy="0 0 0" xyz="0 0 -0.0366"/>
    <axis xyz="0 1 0"/>
    <dynamics damping=".1" friction="0.2"/>
    <limit effort="7.0" lower="-1.57" upper="1.57" velocity="2.208932"/>
  </joint>
  <transmission name="joint12_trans">
    <type>transmission_interface/SimpleTransmission</type>
    <joint name="joint12">
      <hardwareInterface>EffortJointInterface</hardwareInterface>
    </joint>
    <actuator name="joint12_motor">
      <hardwareInterface>EffortJointInterface</hardwareInterface>
      <mechanicalReduction>300</mechanicalReduction>
    </actuator>
  </transmission>
  <link name="joint12__OUTPUT_BODY">
    <visual>
      <origin rpy="-1.57075 0 0" xyz="0 0 0"/>
      <geometry>
        <mesh filename="package://reusnake_visualize/meshes/rotary_output.stl"/>
        <!-- <cylinder radius=".0025" length=".1" /> -->
      </geometry>
      <material name="red">
        <color rgba=".82 0.06 0.06 1"/>
      </material>
    </visual>
    <collision>
      <origin rpy="0 0 0" xyz="0 0 -0.0183"/>
      <geometry>
        <cylinder length="-0.033" radius="0.026"/>
      </geometry>
    </collision>
    <inertial>
      <origin rpy="0 0 0" xyz="0 0 0"/>
      <mass value="0.103"/>
      <inertia ixx="5.4796e-05" ixy="0" ixz="0" iyy="5.4796e-05" iyz="0" izz="3.4814e-05"/>
    </inertial>
  </link>
  <joint name="joint12__OUTPUT_INTERFACE" type="fixed">
    <parent link="joint12__OUTPUT_BODY"/>
    <child link="joint13__INPUT_INTERFACE"/>
    <origin rpy="0 0 -1.57075" xyz="0 0 -0.0273"/>
  </joint>
  <link name="joint13__INPUT_INTERFACE">
    <visual>
      <origin rpy="-1.57075 0 0" xyz="0 0 -0.035"/>
      <geometry>
        <mesh filename="package://reusnake_visualize/meshes/rotary_input.stl"/>
      </geometry>
      <material name="red">
        <color rgba=".82 0.06 0.06 1"/>
      </material>
    </visual>
    <collision>
      <origin rpy="0 0 0" xyz="0 0 -0.0183"/>
      <geometry>
        <cylinder length="-0.033" radius="0.026"/>
      </geometry>
    </collision>
    <inertial>
      <origin rpy="0 0 0" xyz="0 0 -0.0366"/>
      <mass value="0.103"/>
      <inertia ixx="5.4796e-05" ixy="0" ixz="0" iyy="5.4796e-05" iyz="0" izz="3.4814e-05"/>
    </inertial>
  </link>
  <link name="joint13__INPUT_INTERFACE__COLLAR">
    <visual>
      <origin rpy="0 0 0" xyz="0 0 0.005"/>
      <geometry>
        <cylinder length="0.01" radius="0.026"/>
      </geometry>
      <material name="black">
        <color rgba="0 0 0 1"/>
      </material>
    </visual>
  </link>
  <joint name="joint13__INPUT_INTERFACE__COLLAR_JOINT" type="fixed">
    <parent link="joint13__INPUT_INTERFACE"/>
    <child link="joint13__INPUT_INTERFACE__COLLAR"/>
  </joint>
  <joint name="joint13" type="revolute">
    <parent link="joint13__INPUT_INTERFACE"/>
    <child link="joint13__OUTPUT_BODY"/>
    <origin rpy="0 0 0" xyz="0 0 -0.0366"/>
    <axis xyz="0 1 0"/>
    <dynamics damping=".1" friction="0.2"/>
    <limit effort="7.0" lower="-1.57" upper="1.57" velocity="2.208932"/>
  </joint>
  <transmission name="joint13_trans">
    <type>transmission_interface/SimpleTransmission</type>
    <joint name="joint13">
      <hardwareInterface>EffortJointInterface</hardwareInterface>
    </joint>
    <actuator name="joint13_motor">
      <hardwareInterface>EffortJointInterface</hardwareInterface>
      <mechanicalReduction>300</mechanicalReduction>
    </actuator>
  </transmission>
  <link name="joint13__OUTPUT_BODY">
    <visual>
      <origin rpy="-1.57075 0 0" xyz="0 0 0"/>
      <geometry>
        <mesh filename="package://reusnake_visualize/meshes/rotary_output.stl"/>
        <!-- <cylinder radius=".0025" length=".1" /> -->
      </geometry>
      <material name="red">
        <color rgba=".82 0.06 0.06 1"/>
      </material>
    </visual>
    <collision>
      <origin rpy="0 0 0" xyz="0 0 -0.0183"/>
      <geometry>
        <cylinder length="-0.033" radius="0.026"/>
      </geometry>
    </collision>
    <inertial>
      <origin rpy="0 0 0" xyz="0 0 0"/>
      <mass value="0.103"/>
      <inertia ixx="5.4796e-05" ixy="0" ixz="0" iyy="5.4796e-05" iyz="0" izz="3.4814e-05"/>
    </inertial>
  </link>
  <joint name="joint13__OUTPUT_INTERFACE" type="fixed">
    <parent link="joint13__OUTPUT_BODY"/>
    <child link="joint14__INPUT_INTERFACE"/>
    <origin rpy="0 0 -1.57075" xyz="0 0 -0.0273"/>
  </joint>
  <link name="joint14__INPUT_INTERFACE">
    <visual>
      <origin rpy="-1.57075 0 0" xyz="0 0 -0.035"/>
      <geometry>
        <mesh filename="package://reusnake_visualize/meshes/rotary_input.stl"/>
      </geometry>
      <material name="red">
        <color rgba=".82 0.06 0.06 1"/>
      </material>
    </visual>
    <collision>
      <origin rpy="0 0 0" xyz="0 0 -0.0183"/>
      <geometry>
        <cylinder length="-0.033" radius="0.026"/>
      </geometry>
    </collision>
    <inertial>
      <origin rpy="0 0 0" xyz="0 0 -0.0366"/>
      <mass value="0.103"/>
      <inertia ixx="5.4796e-05" ixy="0" ixz="0" iyy="5.4796e-05" iyz="0" izz="3.4814e-05"/>
    </inertial>
  </link>
  <link name="joint14__INPUT_INTERFACE__COLLAR">
    <visual>
      <origin rpy="0 0 0" xyz="0 0 0.005"/>
      <geometry>
        <cylinder length="0.01" radius="0.026"/>
      </geometry>
      <material name="black">
        <color rgba="0 0 0 1"/>
      </material>
    </visual>
  </link>
  <joint name="joint14__INPUT_INTERFACE__COLLAR_JOINT" type="fixed">
    <parent link="joint14__INPUT_INTERFACE"/>
    <child link="joint14__INPUT_INTERFACE__COLLAR"/>
  </joint>
  <joint name="joint14" type="revolute">
    <parent link="joint14__INPUT_INTERFACE"/>
    <child link="joint14__OUTPUT_BODY"/>
    <origin rpy="0 0 0" xyz="0 0 -0.0366"/>
    <axis xyz="0 1 0"/>
    <dynamics damping=".1" friction="0.2"/>
    <limit effort="7.0" lower="-1.57" upper="1.57" velocity="2.208932"/>
  </joint>
  <transmission name="joint14_trans">
    <type>transmission_interface/SimpleTransmission</type>
    <joint name="joint14">
      <hardwareInterface>EffortJointInterface</hardwareInterface>
    </joint>
    <actuator name="joint14_motor">
      <hardwareInterface>EffortJointInterface</hardwareInterface>
      <mechanicalReduction>300</mechanicalReduction>
    </actuator>
  </transmission>
  <link name="joint14__OUTPUT_BODY">
    <visual>
      <origin rpy="-1.57075 0 0" xyz="0 0 0"/>
      <geometry>
        <mesh filename="package://reusnake_visualize/meshes/rotary_output.stl"/>
        <!-- <cylinder radius=".0025" length=".1" /> -->
      </geometry>
      <material name="red">
        <color rgba=".82 0.06 0.06 1"/>
      </material>
    </visual>
    <collision>
      <origin rpy="0 0 0" xyz="0 0 -0.0183"/>
      <geometry>
        <cylinder length="-0.033" radius="0.026"/>
      </geometry>
    </collision>
    <inertial>
      <origin rpy="0 0 0" xyz="0 0 0"/>
      <mass value="0.103"/>
      <inertia ixx="5.4796e-05" ixy="0" ixz="0" iyy="5.4796e-05" iyz="0" izz="3.4814e-05"/>
    </inertial>
  </link>
</robot>
