<?xml version="1.0" ?>
<!-- =================================================================================== -->
<!-- |    This document was autogenerated by xacro from snake.urdf.xacro               | -->
<!-- |    EDITING THIS FILE BY HAND IS NOT RECOMMENDED                                 | -->
<!-- =================================================================================== -->
<robot name="reusnake" xmlns:xacro="http://www.ros.org/wiki/xacro">
  <link name="link0">
    <inertial>
      <origin rpy="0 0 0 " xyz="0.026 0 0"/>
      <mass value="0.2"/>
      <inertia ixx="0.00086666" ixy="0" ixz="0" iyy="0.00086666" iyz="0" izz="0.00086666"/>
    </inertial>
    <visual>
      <geometry>
        <box size="0.052 0.052 0.052"/>
      </geometry>
      <material name="blue">
        <color rgba="0 0 .8 1"/>
      </material>
    </visual>
    <collision>
      <geometry>
        <box size="0.052 0.052 0.052"/>
      </geometry>
    </collision>
  </link>
  <joint name="joint1" type="revolute">
    <origin rpy="0     0 0" xyz="0.052 0 0"/>
    <parent link="link0"/>
    <child link="link1"/>
    <axis xyz="0 0 1"/>
    <dynamics damping=".1" friction="0.2"/>
    <limit effort="20.0" lower="-3.14159265359" upper="3.14159265359" velocity="3.14159265"/>
  </joint>
  <link name="link1">
    <inertial>
      <origin rpy="0 0 0 " xyz="0.026 0 0"/>
      <mass value="0.2"/>
      <inertia ixx="0.00086666" ixy="0" ixz="0" iyy="0.00086666" iyz="0" izz="0.00086666"/>
    </inertial>
    <visual>
      <geometry>
        <box size="0.052 0.052 0.052"/>
      </geometry>
      <material name="blue">
        <color rgba="0 0 .8 1"/>
      </material>
    </visual>
    <collision>
      <geometry>
        <box size="0.052 0.052 0.052"/>
      </geometry>
    </collision>
  </link>
  <joint name="joint2" type="revolute">
    <origin rpy="1.57079 0 0" xyz="0.052 0 0"/>
    <parent link="link1"/>
    <child link="link2"/>
    <axis xyz="0 0 1"/>
    <dynamics damping=".1" friction="0.2"/>
    <limit effort="20.0" lower="-3.14159265359" upper="3.14159265359" velocity="3.14159265"/>
  </joint>
  <transmission name="1_trans">
    <type>transmission_interface/SimpleTransmission</type>
    <joint name="joint1">
      <hardwareInterface>hardware_interface/EffortJointInterface</hardwareInterface>
    </joint>
    <actuator name="$joint1_motor">
      <hardwareInterface>hardware_interface/EffortJointInterface</hardwareInterface>
      <mechanicalReduction>300</mechanicalReduction>
    </actuator>
  </transmission>
  <link name="link2">
    <inertial>
      <origin rpy="0 0 0 " xyz="0.026 0 0"/>
      <mass value="0.2"/>
      <inertia ixx="0.00086666" ixy="0" ixz="0" iyy="0.00086666" iyz="0" izz="0.00086666"/>
    </inertial>
    <visual>
      <geometry>
        <box size="0.052 0.052 0.052"/>
      </geometry>
      <material name="blue">
        <color rgba="0 0 .8 1"/>
      </material>
    </visual>
    <collision>
      <geometry>
        <box size="0.052 0.052 0.052"/>
      </geometry>
    </collision>
  </link>
  <joint name="joint3" type="revolute">
    <origin rpy="1.57079 0 0" xyz="0.052 0 0"/>
    <parent link="link2"/>
    <child link="link3"/>
    <axis xyz="0 0 1"/>
    <dynamics damping=".1" friction="0.2"/>
    <limit effort="20.0" lower="-3.14159265359" upper="3.14159265359" velocity="3.14159265"/>
  </joint>
  <transmission name="2_trans">
    <type>transmission_interface/SimpleTransmission</type>
    <joint name="joint2">
      <hardwareInterface>hardware_interface/EffortJointInterface</hardwareInterface>
    </joint>
    <actuator name="$joint2_motor">
      <hardwareInterface>hardware_interface/EffortJointInterface</hardwareInterface>
      <mechanicalReduction>300</mechanicalReduction>
    </actuator>
  </transmission>
  <link name="link3">
    <inertial>
      <origin rpy="0 0 0 " xyz="0.026 0 0"/>
      <mass value="0.2"/>
      <inertia ixx="0.00086666" ixy="0" ixz="0" iyy="0.00086666" iyz="0" izz="0.00086666"/>
    </inertial>
    <visual>
      <geometry>
        <box size="0.052 0.052 0.052"/>
      </geometry>
      <material name="blue">
        <color rgba="0 0 .8 1"/>
      </material>
    </visual>
    <collision>
      <geometry>
        <box size="0.052 0.052 0.052"/>
      </geometry>
    </collision>
  </link>
  <joint name="joint4" type="revolute">
    <origin rpy="1.57079 0 0" xyz="0.052 0 0"/>
    <parent link="link3"/>
    <child link="link4"/>
    <axis xyz="0 0 1"/>
    <dynamics damping=".1" friction="0.2"/>
    <limit effort="20.0" lower="-3.14159265359" upper="3.14159265359" velocity="3.14159265"/>
  </joint>
  <transmission name="3_trans">
    <type>transmission_interface/SimpleTransmission</type>
    <joint name="joint3">
      <hardwareInterface>hardware_interface/EffortJointInterface</hardwareInterface>
    </joint>
    <actuator name="$joint3_motor">
      <hardwareInterface>hardware_interface/EffortJointInterface</hardwareInterface>
      <mechanicalReduction>300</mechanicalReduction>
    </actuator>
  </transmission>
  <link name="link4">
    <inertial>
      <origin rpy="0 0 0 " xyz="0.026 0 0"/>
      <mass value="0.2"/>
      <inertia ixx="0.00086666" ixy="0" ixz="0" iyy="0.00086666" iyz="0" izz="0.00086666"/>
    </inertial>
    <visual>
      <geometry>
        <box size="0.052 0.052 0.052"/>
      </geometry>
      <material name="blue">
        <color rgba="0 0 .8 1"/>
      </material>
    </visual>
    <collision>
      <geometry>
        <box size="0.052 0.052 0.052"/>
      </geometry>
    </collision>
  </link>
  <joint name="joint5" type="revolute">
    <origin rpy="1.57079 0 0" xyz="0.052 0 0"/>
    <parent link="link4"/>
    <child link="link5"/>
    <axis xyz="0 0 1"/>
    <dynamics damping=".1" friction="0.2"/>
    <limit effort="20.0" lower="-3.14159265359" upper="3.14159265359" velocity="3.14159265"/>
  </joint>
  <transmission name="4_trans">
    <type>transmission_interface/SimpleTransmission</type>
    <joint name="joint4">
      <hardwareInterface>hardware_interface/EffortJointInterface</hardwareInterface>
    </joint>
    <actuator name="$joint4_motor">
      <hardwareInterface>hardware_interface/EffortJointInterface</hardwareInterface>
      <mechanicalReduction>300</mechanicalReduction>
    </actuator>
  </transmission>
  <link name="link5">
    <inertial>
      <origin rpy="0 0 0 " xyz="0.026 0 0"/>
      <mass value="0.2"/>
      <inertia ixx="0.00086666" ixy="0" ixz="0" iyy="0.00086666" iyz="0" izz="0.00086666"/>
    </inertial>
    <visual>
      <geometry>
        <box size="0.052 0.052 0.052"/>
      </geometry>
      <material name="blue">
        <color rgba="0 0 .8 1"/>
      </material>
    </visual>
    <collision>
      <geometry>
        <box size="0.052 0.052 0.052"/>
      </geometry>
    </collision>
  </link>
  <joint name="joint6" type="revolute">
    <origin rpy="1.57079 0 0" xyz="0.052 0 0"/>
    <parent link="link5"/>
    <child link="link6"/>
    <axis xyz="0 0 1"/>
    <dynamics damping=".1" friction="0.2"/>
    <limit effort="20.0" lower="-3.14159265359" upper="3.14159265359" velocity="3.14159265"/>
  </joint>
  <transmission name="5_trans">
    <type>transmission_interface/SimpleTransmission</type>
    <joint name="joint5">
      <hardwareInterface>hardware_interface/EffortJointInterface</hardwareInterface>
    </joint>
    <actuator name="$joint5_motor">
      <hardwareInterface>hardware_interface/EffortJointInterface</hardwareInterface>
      <mechanicalReduction>300</mechanicalReduction>
    </actuator>
  </transmission>
  <link name="link6">
    <inertial>
      <origin rpy="0 0 0 " xyz="0.026 0 0"/>
      <mass value="0.2"/>
      <inertia ixx="0.00086666" ixy="0" ixz="0" iyy="0.00086666" iyz="0" izz="0.00086666"/>
    </inertial>
    <visual>
      <geometry>
        <box size="0.052 0.052 0.052"/>
      </geometry>
      <material name="blue">
        <color rgba="0 0 .8 1"/>
      </material>
    </visual>
    <collision>
      <geometry>
        <box size="0.052 0.052 0.052"/>
      </geometry>
    </collision>
  </link>
  <joint name="joint7" type="revolute">
    <origin rpy="1.57079 0 0" xyz="0.052 0 0"/>
    <parent link="link6"/>
    <child link="link7"/>
    <axis xyz="0 0 1"/>
    <dynamics damping=".1" friction="0.2"/>
    <limit effort="20.0" lower="-3.14159265359" upper="3.14159265359" velocity="3.14159265"/>
  </joint>
  <transmission name="6_trans">
    <type>transmission_interface/SimpleTransmission</type>
    <joint name="joint6">
      <hardwareInterface>hardware_interface/EffortJointInterface</hardwareInterface>
    </joint>
    <actuator name="$joint6_motor">
      <hardwareInterface>hardware_interface/EffortJointInterface</hardwareInterface>
      <mechanicalReduction>300</mechanicalReduction>
    </actuator>
  </transmission>
  <link name="link7">
    <inertial>
      <origin rpy="0 0 0 " xyz="0.026 0 0"/>
      <mass value="0.2"/>
      <inertia ixx="0.00086666" ixy="0" ixz="0" iyy="0.00086666" iyz="0" izz="0.00086666"/>
    </inertial>
    <visual>
      <geometry>
        <box size="0.052 0.052 0.052"/>
      </geometry>
      <material name="blue">
        <color rgba="0 0 .8 1"/>
      </material>
    </visual>
    <collision>
      <geometry>
        <box size="0.052 0.052 0.052"/>
      </geometry>
    </collision>
  </link>
  <joint name="joint8" type="revolute">
    <origin rpy="1.57079 0 0" xyz="0.052 0 0"/>
    <parent link="link7"/>
    <child link="link8"/>
    <axis xyz="0 0 1"/>
    <dynamics damping=".1" friction="0.2"/>
    <limit effort="20.0" lower="-3.14159265359" upper="3.14159265359" velocity="3.14159265"/>
  </joint>
  <transmission name="7_trans">
    <type>transmission_interface/SimpleTransmission</type>
    <joint name="joint7">
      <hardwareInterface>hardware_interface/EffortJointInterface</hardwareInterface>
    </joint>
    <actuator name="$joint7_motor">
      <hardwareInterface>hardware_interface/EffortJointInterface</hardwareInterface>
      <mechanicalReduction>300</mechanicalReduction>
    </actuator>
  </transmission>
  <link name="link8">
    <inertial>
      <origin rpy="0 0 0 " xyz="0.026 0 0"/>
      <mass value="0.2"/>
      <inertia ixx="0.00086666" ixy="0" ixz="0" iyy="0.00086666" iyz="0" izz="0.00086666"/>
    </inertial>
    <visual>
      <geometry>
        <box size="0.052 0.052 0.052"/>
      </geometry>
      <material name="blue">
        <color rgba="0 0 .8 1"/>
      </material>
    </visual>
    <collision>
      <geometry>
        <box size="0.052 0.052 0.052"/>
      </geometry>
    </collision>
  </link>
  <joint name="joint9" type="revolute">
    <origin rpy="1.57079 0 0" xyz="0.052 0 0"/>
    <parent link="link8"/>
    <child link="link9"/>
    <axis xyz="0 0 1"/>
    <dynamics damping=".1" friction="0.2"/>
    <limit effort="20.0" lower="-3.14159265359" upper="3.14159265359" velocity="3.14159265"/>
  </joint>
  <transmission name="8_trans">
    <type>transmission_interface/SimpleTransmission</type>
    <joint name="joint8">
      <hardwareInterface>hardware_interface/EffortJointInterface</hardwareInterface>
    </joint>
    <actuator name="$joint8_motor">
      <hardwareInterface>hardware_interface/EffortJointInterface</hardwareInterface>
      <mechanicalReduction>300</mechanicalReduction>
    </actuator>
  </transmission>
  <link name="link9">
    <inertial>
      <origin rpy="0 0 0 " xyz="0.026 0 0"/>
      <mass value="0.2"/>
      <inertia ixx="0.00086666" ixy="0" ixz="0" iyy="0.00086666" iyz="0" izz="0.00086666"/>
    </inertial>
    <visual>
      <geometry>
        <box size="0.052 0.052 0.052"/>
      </geometry>
      <material name="blue">
        <color rgba="0 0 .8 1"/>
      </material>
    </visual>
    <collision>
      <geometry>
        <box size="0.052 0.052 0.052"/>
      </geometry>
    </collision>
  </link>
  <joint name="joint10" type="revolute">
    <origin rpy="1.57079 0 0" xyz="0.052 0 0"/>
    <parent link="link9"/>
    <child link="link10"/>
    <axis xyz="0 0 1"/>
    <dynamics damping=".1" friction="0.2"/>
    <limit effort="20.0" lower="-3.14159265359" upper="3.14159265359" velocity="3.14159265"/>
  </joint>
  <transmission name="9_trans">
    <type>transmission_interface/SimpleTransmission</type>
    <joint name="joint9">
      <hardwareInterface>hardware_interface/EffortJointInterface</hardwareInterface>
    </joint>
    <actuator name="$joint9_motor">
      <hardwareInterface>hardware_interface/EffortJointInterface</hardwareInterface>
      <mechanicalReduction>300</mechanicalReduction>
    </actuator>
  </transmission>
  <link name="link10">
    <inertial>
      <origin rpy="0 0 0 " xyz="0.026 0 0"/>
      <mass value="0.2"/>
      <inertia ixx="0.00086666" ixy="0" ixz="0" iyy="0.00086666" iyz="0" izz="0.00086666"/>
    </inertial>
    <visual>
      <geometry>
        <box size="0.052 0.052 0.052"/>
      </geometry>
      <material name="blue">
        <color rgba="0 0 .8 1"/>
      </material>
    </visual>
    <collision>
      <geometry>
        <box size="0.052 0.052 0.052"/>
      </geometry>
    </collision>
  </link>
  <joint name="joint11" type="revolute">
    <origin rpy="1.57079 0 0" xyz="0.052 0 0"/>
    <parent link="link10"/>
    <child link="link11"/>
    <axis xyz="0 0 1"/>
    <dynamics damping=".1" friction="0.2"/>
    <limit effort="20.0" lower="-3.14159265359" upper="3.14159265359" velocity="3.14159265"/>
  </joint>
  <transmission name="10_trans">
    <type>transmission_interface/SimpleTransmission</type>
    <joint name="joint10">
      <hardwareInterface>hardware_interface/EffortJointInterface</hardwareInterface>
    </joint>
    <actuator name="$joint10_motor">
      <hardwareInterface>hardware_interface/EffortJointInterface</hardwareInterface>
      <mechanicalReduction>300</mechanicalReduction>
    </actuator>
  </transmission>
  <link name="link11">
    <inertial>
      <origin rpy="0 0 0 " xyz="0.026 0 0"/>
      <mass value="0.2"/>
      <inertia ixx="0.00086666" ixy="0" ixz="0" iyy="0.00086666" iyz="0" izz="0.00086666"/>
    </inertial>
    <visual>
      <geometry>
        <box size="0.052 0.052 0.052"/>
      </geometry>
      <material name="blue">
        <color rgba="0 0 .8 1"/>
      </material>
    </visual>
    <collision>
      <geometry>
        <box size="0.052 0.052 0.052"/>
      </geometry>
    </collision>
  </link>
  <joint name="joint12" type="revolute">
    <origin rpy="1.57079 0 0" xyz="0.052 0 0"/>
    <parent link="link11"/>
    <child link="link12"/>
    <axis xyz="0 0 1"/>
    <dynamics damping=".1" friction="0.2"/>
    <limit effort="20.0" lower="-3.14159265359" upper="3.14159265359" velocity="3.14159265"/>
  </joint>
  <transmission name="11_trans">
    <type>transmission_interface/SimpleTransmission</type>
    <joint name="joint11">
      <hardwareInterface>hardware_interface/EffortJointInterface</hardwareInterface>
    </joint>
    <actuator name="$joint11_motor">
      <hardwareInterface>hardware_interface/EffortJointInterface</hardwareInterface>
      <mechanicalReduction>300</mechanicalReduction>
    </actuator>
  </transmission>
  <link name="link12">
    <inertial>
      <origin rpy="0 0 0 " xyz="0.026 0 0"/>
      <mass value="0.2"/>
      <inertia ixx="0.00086666" ixy="0" ixz="0" iyy="0.00086666" iyz="0" izz="0.00086666"/>
    </inertial>
    <visual>
      <geometry>
        <box size="0.052 0.052 0.052"/>
      </geometry>
      <material name="blue">
        <color rgba="0 0 .8 1"/>
      </material>
    </visual>
    <collision>
      <geometry>
        <box size="0.052 0.052 0.052"/>
      </geometry>
    </collision>
  </link>
  <joint name="joint13" type="revolute">
    <origin rpy="1.57079 0 0" xyz="0.052 0 0"/>
    <parent link="link12"/>
    <child link="link13"/>
    <axis xyz="0 0 1"/>
    <dynamics damping=".1" friction="0.2"/>
    <limit effort="20.0" lower="-3.14159265359" upper="3.14159265359" velocity="3.14159265"/>
  </joint>
  <transmission name="12_trans">
    <type>transmission_interface/SimpleTransmission</type>
    <joint name="joint12">
      <hardwareInterface>hardware_interface/EffortJointInterface</hardwareInterface>
    </joint>
    <actuator name="$joint12_motor">
      <hardwareInterface>hardware_interface/EffortJointInterface</hardwareInterface>
      <mechanicalReduction>300</mechanicalReduction>
    </actuator>
  </transmission>
  <link name="link13">
    <inertial>
      <origin rpy="0 0 0 " xyz="0.026 0 0"/>
      <mass value="0.2"/>
      <inertia ixx="0.00086666" ixy="0" ixz="0" iyy="0.00086666" iyz="0" izz="0.00086666"/>
    </inertial>
    <visual>
      <geometry>
        <box size="0.052 0.052 0.052"/>
      </geometry>
      <material name="blue">
        <color rgba="0 0 .8 1"/>
      </material>
    </visual>
    <collision>
      <geometry>
        <box size="0.052 0.052 0.052"/>
      </geometry>
    </collision>
  </link>
  <joint name="joint14" type="revolute">
    <origin rpy="1.57079 0 0" xyz="0.052 0 0"/>
    <parent link="link13"/>
    <child link="link14"/>
    <axis xyz="0 0 1"/>
    <dynamics damping=".1" friction="0.2"/>
    <limit effort="20.0" lower="-3.14159265359" upper="3.14159265359" velocity="3.14159265"/>
  </joint>
  <transmission name="13_trans">
    <type>transmission_interface/SimpleTransmission</type>
    <joint name="joint13">
      <hardwareInterface>hardware_interface/EffortJointInterface</hardwareInterface>
    </joint>
    <actuator name="$joint13_motor">
      <hardwareInterface>hardware_interface/EffortJointInterface</hardwareInterface>
      <mechanicalReduction>300</mechanicalReduction>
    </actuator>
  </transmission>
  <link name="link14">
    <inertial>
      <origin rpy="0 0 0 " xyz="0.026 0 0"/>
      <mass value="0.2"/>
      <inertia ixx="0.00086666" ixy="0" ixz="0" iyy="0.00086666" iyz="0" izz="0.00086666"/>
    </inertial>
    <visual>
      <geometry>
        <box size="0.052 0.052 0.052"/>
      </geometry>
      <material name="blue">
        <color rgba="0 0 .8 1"/>
      </material>
    </visual>
    <collision>
      <geometry>
        <box size="0.052 0.052 0.052"/>
      </geometry>
    </collision>
  </link>
</robot>
